Workbook

Sheet Polo Orders
A1: Polo Order, Return & Surplus Tracker | N1: Size Summary — Returns Added Back
A2: Select the returned shirt size separately. Returned shirts are added back to the matching size totals and Surplus.
N3: Polo Size | O3: Orders | P3: Short Sleeve | Q3: Long Sleeve | R3: Return Short | S3: Return Long | T3: Surplus | U3: Net Issued | V3: Short Sleeve to Actually Order | W3: Long Sleeve to Actually Order | X3: Total to Actually Order
A4: Employee Name | B4: Order Size | C4: Short Sleeve | D4: Long Sleeve | E4: Combo | F4: Return Short Size | G4: Return Short Qty | H4: Return Long Size | I4: Return Long Qty | J4: Surplus | K4: Net Issued | L4: Delivered to Tech | N4: =IF('Size Setup'!A3="","",'Size Setup'!A3) -> M | O4: =IF(N4="","",COUNTIF($B$5:$B$54,N4)+SUMIF($F$5:$F$54,N4,$G$5:$G$54)+SUMIF($H$5:$H$54,N4,$I$5:$I$54)) -> 6 | P4: =IF(N4="","",SUMIF($B$5:$B$54,N4,$C$5:$C$54)+SUMIF($F$5:$F$54,N4,$G$5:$G$54)) -> 11 | Q4: =IF(N4="","",SUMIF($B$5:$B$54,N4,$D$5:$D$54)+SUMIF($H$5:$H$54,N4,$I$5:$I$54)) -> 3 | R4: =IF(N4="","",SUMIF($F$5:$F$54,N4,$G$5:$G$54)) -> 1 | S4: =IF(N4="","",SUMIF($H$5:$H$54,N4,$I$5:$I$54)) -> 0 | T4: =IF(N4="","",R4+S4) -> 1 | U4: =IF(N4="","",MAX(0,SUMIF($B$5:$B$54,N4,$C$5:$C$54)+SUMIF($B$5:$B$54,N4,$D$5:$D$54)-R4-S4)) -> 12 | V4: =IF(N4="","",MAX(0,SUMIF($B$5:$B$54,N4,$C$5:$C$54)-R4)) -> 9 | W4: =IF(N4="","",MAX(0,SUMIF($B$5:$B$54,N4,$D$5:$D$54)-S4)) -> 3 | X4: =IF(N4="","",V4+W4) -> 12
A5: Peter Gonzalez | B5: M | C5: 3 | D5: 0 | E5: =IF(B5="","",IF(AND(C5>0,D5>0),C5&" Short Sleeve + "&D5&" Long Sleeve",IF(C5>0,C5&" Short Sleeve",IF(D5>0,D5&" Long Sleeve","")))) -> 3 Short Sleeve | G5: 0 | I5: 0 | J5: =IF(A5="","",N(G5)+N(I5)) -> 0 | K5: =IF(A5="","",MAX(0,N(C5)+N(D5)-N(G5)-N(I5))) -> 3 | N5: =IF('Size Setup'!A4="","",'Size Setup'!A4) -> L | O5: =IF(N5="","",COUNTIF($B$5:$B$54,N5)+SUMIF($F$5:$F$54,N5,$G$5:$G$54)+SUMIF($H$5:$H$54,N5,$I$5:$I$54)) -> 7 | P5: =IF(N5="","",SUMIF($B$5:$B$54,N5,$C$5:$C$54)+SUMIF($F$5:$F$54,N5,$G$5:$G$54)) -> 6 | Q5: =IF(N5="","",SUMIF($B$5:$B$54,N5,$D$5:$D$54)+SUMIF($H$5:$H$54,N5,$I$5:$I$54)) -> 5 | R5: =IF(N5="","",SUMIF($F$5:$F$54,N5,$G$5:$G$54)) -> 2 | S5: =IF(N5="","",SUMIF($H$5:$H$54,N5,$I$5:$I$54)) -> 2 | T5: =IF(N5="","",R5+S5) -> 4 | U5: =IF(N5="","",MAX(0,SUMIF($B$5:$B$54,N5,$C$5:$C$54)+SUMIF($B$5:$B$54,N5,$D$5:$D$54)-R5-S5)) -> 3 | V5: =IF(N5="","",MAX(0,SUMIF($B$5:$B$54,N5,$C$5:$C$54)-R5)) -> 2 | W5: =IF(N5="","",MAX(0,SUMIF($B$5:$B$54,N5,$D$5:$D$54)-S5)) -> 1 | X5: =IF(N5="","",V5+W5) -> 3
A6: Alvaro Hernandez | B6: XL | C6: 3 | D6: 0 | E6: =IF(B6="","",IF(AND(C6>0,D6>0),C6&" Short Sleeve + "&D6&" Long Sleeve",IF(C6>0,C6&" Short Sleeve",IF(D6>0,D6&" Long Sleeve","")))) -> 3 Short Sleeve | G6: 0 | I6: 0 | J6: =IF(A6="","",N(G6)+N(I6)) -> 0 | K6: =IF(A6="","",MAX(0,N(C6)+N(D6)-N(G6)-N(I6))) -> 3 | N6: =IF('Size Setup'!A5="","",'Size Setup'!A5) -> XL | O6: =IF(N6="","",COUNTIF($B$5:$B$54,N6)+SUMIF($F$5:$F$54,N6,$G$5:$G$54)+SUMIF($H$5:$H$54,N6,$I$5:$I$54)) -> 2 | P6: =IF(N6="","",SUMIF($B$5:$B$54,N6,$C$5:$C$54)+SUMIF($F$5:$F$54,N6,$G$5:$G$54)) -> 6 | Q6: =IF(N6="","",SUMIF($B$5:$B$54,N6,$D$5:$D$54)+SUMIF($H$5:$H$54,N6,$I$5:$I$54)) -> 0 | R6: =IF(N6="","",SUMIF($F$5:$F$54,N6,$G$5:$G$54)) -> 0 | S6: =IF(N6="","",SUMIF($H$5:$H$54,N6,$I$5:$I$54)) -> 0 | T6: =IF(N6="","",R6+S6) -> 0 | U6: =IF(N6="","",MAX(0,SUMIF($B$5:$B$54,N6,$C$5:$C$54)+SUMIF($B$5:$B$54,N6,$D$5:$D$54)-R6-S6)) -> 6 | V6: =IF(N6="","",MAX(0,SUMIF($B$5:$B$54,N6,$C$5:$C$54)-R6)) -> 6 | W6: =IF(N6="","",MAX(0,SUMIF($B$5:$B$54,N6,$D$5:$D$54)-S6)) -> 0 | X6: =IF(N6="","",V6+W6) -> 6
A7: Jonathan Davila | B7: L | C7: 2 | D7: 1 | E7: =IF(B7="","",IF(AND(C7>0,D7>0),C7&" Short Sleeve + "&D7&" Long Sleeve",IF(C7>0,C7&" Short Sleeve",IF(D7>0,D7&" Long Sleeve","")))) -> 2 Short Sleeve + 1 Long Sleeve | G7: 0 | I7: 0 | J7: =IF(A7="","",N(G7)+N(I7)) -> 0 | K7: =IF(A7="","",MAX(0,N(C7)+N(D7)-N(G7)-N(I7))) -> 3 | N7: =IF('Size Setup'!A6="","",'Size Setup'!A6) -> W S | O7: =IF(N7="","",COUNTIF($B$5:$B$54,N7)+SUMIF($F$5:$F$54,N7,$G$5:$G$54)+SUMIF($H$5:$H$54,N7,$I$5:$I$54)) -> 1 | P7: =IF(N7="","",SUMIF($B$5:$B$54,N7,$C$5:$C$54)+SUMIF($F$5:$F$54,N7,$G$5:$G$54)) -> 2 | Q7: =IF(N7="","",SUMIF($B$5:$B$54,N7,$D$5:$D$54)+SUMIF($H$5:$H$54,N7,$I$5:$I$54)) -> 1 | R7: =IF(N7="","",SUMIF($F$5:$F$54,N7,$G$5:$G$54)) -> 0 | S7: =IF(N7="","",SUMIF($H$5:$H$54,N7,$I$5:$I$54)) -> 0 | T7: =IF(N7="","",R7+S7) -> 0 | U7: =IF(N7="","",MAX(0,SUMIF($B$5:$B$54,N7,$C$5:$C$54)+SUMIF($B$5:$B$54,N7,$D$5:$D$54)-R7-S7)) -> 3 | V7: =IF(N7="","",MAX(0,SUMIF($B$5:$B$54,N7,$C$5:$C$54)-R7)) -> 2 | W7: =IF(N7="","",MAX(0,SUMIF($B$5:$B$54,N7,$D$5:$D$54)-S7)) -> 1 | X7: =IF(N7="","",V7+W7) -> 3
A8: Anthony Thompson | B8: M | C8: 2 | D8: 1 | E8: =IF(B8="","",IF(AND(C8>0,D8>0),C8&" Short Sleeve + "&D8&" Long Sleeve",IF(C8>0,C8&" Short Sleeve",IF(D8>0,D8&" Long Sleeve","")))) -> 2 Short Sleeve + 1 Long Sleeve | F8: L | G8: 1 | H8: L | I8: 1 | J8: =IF(A8="","",N(G8)+N(I8)) -> 2 | K8: =IF(A8="","",MAX(0,N(C8)+N(D8)-N(G8)-N(I8))) -> 1 | N8: =IF('Size Setup'!A7="","",'Size Setup'!A7) | O8: =IF(N8="","",COUNTIF($B$5:$B$54,N8)+SUMIF($F$5:$F$54,N8,$G$5:$G$54)+SUMIF($H$5:$H$54,N8,$I$5:$I$54)) | P8: =IF(N8="","",SUMIF($B$5:$B$54,N8,$C$5:$C$54)+SUMIF($F$5:$F$54,N8,$G$5:$G$54)) | Q8: =IF(N8="","",SUMIF($B$5:$B$54,N8,$D$5:$D$54)+SUMIF($H$5:$H$54,N8,$I$5:$I$54)) | R8: =IF(N8="","",SUMIF($F$5:$F$54,N8,$G$5:$G$54)) | S8: =IF(N8="","",SUMIF($H$5:$H$54,N8,$I$5:$I$54)) | T8: =IF(N8="","",R8+S8) | U8: =IF(N8="","",MAX(0,SUMIF($B$5:$B$54,N8,$C$5:$C$54)+SUMIF($B$5:$B$54,N8,$D$5:$D$54)-R8-S8)) | V8: =IF(N8="","",MAX(0,SUMIF($B$5:$B$54,N8,$C$5:$C$54)-R8)) | W8: =IF(N8="","",MAX(0,SUMIF($B$5:$B$54,N8,$D$5:$D$54)-S8)) | X8: =IF(N8="","",V8+W8)
A9: Andrew Montgomery | B9: M | C9: 3 | D9: 0 | E9: =IF(B9="","",IF(AND(C9>0,D9>0),C9&" Short Sleeve + "&D9&" Long Sleeve",IF(C9>0,C9&" Short Sleeve",IF(D9>0,D9&" Long Sleeve","")))) -> 3 Short Sleeve | G9: 0 | I9: 0 | J9: =IF(A9="","",N(G9)+N(I9)) -> 0 | K9: =IF(A9="","",MAX(0,N(C9)+N(D9)-N(G9)-N(I9))) -> 3 | N9: =IF('Size Setup'!A8="","",'Size Setup'!A8) | O9: =IF(N9="","",COUNTIF($B$5:$B$54,N9)+SUMIF($F$5:$F$54,N9,$G$5:$G$54)+SUMIF($H$5:$H$54,N9,$I$5:$I$54)) | P9: =IF(N9="","",SUMIF($B$5:$B$54,N9,$C$5:$C$54)+SUMIF($F$5:$F$54,N9,$G$5:$G$54)) | Q9: =IF(N9="","",SUMIF($B$5:$B$54,N9,$D$5:$D$54)+SUMIF($H$5:$H$54,N9,$I$5:$I$54)) | R9: =IF(N9="","",SUMIF($F$5:$F$54,N9,$G$5:$G$54)) | S9: =IF(N9="","",SUMIF($H$5:$H$54,N9,$I$5:$I$54)) | T9: =IF(N9="","",R9+S9) | U9: =IF(N9="","",MAX(0,SUMIF($B$5:$B$54,N9,$C$5:$C$54)+SUMIF($B$5:$B$54,N9,$D$5:$D$54)-R9-S9)) | V9: =IF(N9="","",MAX(0,SUMIF($B$5:$B$54,N9,$C$5:$C$54)-R9)) | W9: =IF(N9="","",MAX(0,SUMIF($B$5:$B$54,N9,$D$5:$D$54)-S9)) | X9: =IF(N9="","",V9+W9)
A10: Carlos Martinez | B10: L | C10: 2 | D10: 1 | E10: =IF(B10="","",IF(AND(C10>0,D10>0),C10&" Short Sleeve + "&D10&" Long Sleeve",IF(C10>0,C10&" Short Sleeve",IF(D10>0,D10&" Long Sleeve","")))) -> 2 Short Sleeve + 1 Long Sleeve | G10: 0 | I10: 0 | J10: =IF(A10="","",N(G10)+N(I10)) -> 0 | K10: =IF(A10="","",MAX(0,N(C10)+N(D10)-N(G10)-N(I10))) -> 3 | N10: =IF('Size Setup'!A9="","",'Size Setup'!A9) | O10: =IF(N10="","",COUNTIF($B$5:$B$54,N10)+SUMIF($F$5:$F$54,N10,$G$5:$G$54)+SUMIF($H$5:$H$54,N10,$I$5:$I$54)) | P10: =IF(N10="","",SUMIF($B$5:$B$54,N10,$C$5:$C$54)+SUMIF($F$5:$F$54,N10,$G$5:$G$54)) | Q10: =IF(N10="","",SUMIF($B$5:$B$54,N10,$D$5:$D$54)+SUMIF($H$5:$H$54,N10,$I$5:$I$54)) | R10: =IF(N10="","",SUMIF($F$5:$F$54,N10,$G$5:$G$54)) | S10: =IF(N10="","",SUMIF($H$5:$H$54,N10,$I$5:$I$54)) | T10: =IF(N10="","",R10+S10) | U10: =IF(N10="","",MAX(0,SUMIF($B$5:$B$54,N10,$C$5:$C$54)+SUMIF($B$5:$B$54,N10,$D$5:$D$54)-R10-S10)) | V10: =IF(N10="","",MAX(0,SUMIF($B$5:$B$54,N10,$C$5:$C$54)-R10)) | W10: =IF(N10="","",MAX(0,SUMIF($B$5:$B$54,N10,$D$5:$D$54)-S10)) | X10: =IF(N10="","",V10+W10)
A11: Carlos Sanabria | B11: XL | C11: 3 | D11: 0 | E11: =IF(B11="","",IF(AND(C11>0,D11>0),C11&" Short Sleeve + "&D11&" Long Sleeve",IF(C11>0,C11&" Short Sleeve",IF(D11>0,D11&" Long Sleeve","")))) -> 3 Short Sleeve | G11: 0 | I11: 0 | J11: =IF(A11="","",N(G11)+N(I11)) -> 0 | K11: =IF(A11="","",MAX(0,N(C11)+N(D11)-N(G11)-N(I11))) -> 3 | N11: =IF('Size Setup'!A10="","",'Size Setup'!A10) | O11: =IF(N11="","",COUNTIF($B$5:$B$54,N11)+SUMIF($F$5:$F$54,N11,$G$5:$G$54)+SUMIF($H$5:$H$54,N11,$I$5:$I$54)) | P11: =IF(N11="","",SUMIF($B$5:$B$54,N11,$C$5:$C$54)+SUMIF($F$5:$F$54,N11,$G$5:$G$54)) | Q11: =IF(N11="","",SUMIF($B$5:$B$54,N11,$D$5:$D$54)+SUMIF($H$5:$H$54,N11,$I$5:$I$54)) | R11: =IF(N11="","",SUMIF($F$5:$F$54,N11,$G$5:$G$54)) | S11: =IF(N11="","",SUMIF($H$5:$H$54,N11,$I$5:$I$54)) | T11: =IF(N11="","",R11+S11) | U11: =IF(N11="","",MAX(0,SUMIF($B$5:$B$54,N11,$C$5:$C$54)+SUMIF($B$5:$B$54,N11,$D$5:$D$54)-R11-S11)) | V11: =IF(N11="","",MAX(0,SUMIF($B$5:$B$54,N11,$C$5:$C$54)-R11)) | W11: =IF(N11="","",MAX(0,SUMIF($B$5:$B$54,N11,$D$5:$D$54)-S11)) | X11: =IF(N11="","",V11+W11)
A12: Amanda Martinez | B12: W S | C12: 2 | D12: 1 | E12: =IF(B12="","",IF(AND(C12>0,D12>0),C12&" Short Sleeve + "&D12&" Long Sleeve",IF(C12>0,C12&" Short Sleeve",IF(D12>0,D12&" Long Sleeve","")))) -> 2 Short Sleeve + 1 Long Sleeve | G12: 0 | I12: 0 | J12: =IF(A12="","",N(G12)+N(I12)) -> 0 | K12: =IF(A12="","",MAX(0,N(C12)+N(D12)-N(G12)-N(I12))) -> 3 | N12: =IF('Size Setup'!A11="","",'Size Setup'!A11) | O12: =IF(N12="","",COUNTIF($B$5:$B$54,N12)+SUMIF($F$5:$F$54,N12,$G$5:$G$54)+SUMIF($H$5:$H$54,N12,$I$5:$I$54)) | P12: =IF(N12="","",SUMIF($B$5:$B$54,N12,$C$5:$C$54)+SUMIF($F$5:$F$54,N12,$G$5:$G$54)) | Q12: =IF(N12="","",SUMIF($B$5:$B$54,N12,$D$5:$D$54)+SUMIF($H$5:$H$54,N12,$I$5:$I$54)) | R12: =IF(N12="","",SUMIF($F$5:$F$54,N12,$G$5:$G$54)) | S12: =IF(N12="","",SUMIF($H$5:$H$54,N12,$I$5:$I$54)) | T12: =IF(N12="","",R12+S12) | U12: =IF(N12="","",MAX(0,SUMIF($B$5:$B$54,N12,$C$5:$C$54)+SUMIF($B$5:$B$54,N12,$D$5:$D$54)-R12-S12)) | V12: =IF(N12="","",MAX(0,SUMIF($B$5:$B$54,N12,$C$5:$C$54)-R12)) | W12: =IF(N12="","",MAX(0,SUMIF($B$5:$B$54,N12,$D$5:$D$54)-S12)) | X12: =IF(N12="","",V12+W12)
A13: Kevin Luburd | B13: M | C13: 2 | D13: 1 | E13: =IF(B13="","",IF(AND(C13>0,D13>0),C13&" Short Sleeve + "&D13&" Long Sleeve",IF(C13>0,C13&" Short Sleeve",IF(D13>0,D13&" Long Sleeve","")))) -> 2 Short Sleeve + 1 Long Sleeve | G13: 0 | I13: 0 | J13: =IF(A13="","",N(G13)+N(I13)) -> 0 | K13: =IF(A13="","",MAX(0,N(C13)+N(D13)-N(G13)-N(I13))) -> 3 | N13: =IF('Size Setup'!A12="","",'Size Setup'!A12) | O13: =IF(N13="","",COUNTIF($B$5:$B$54,N13)+SUMIF($F$5:$F$54,N13,$G$5:$G$54)+SUMIF($H$5:$H$54,N13,$I$5:$I$54)) | P13: =IF(N13="","",SUMIF($B$5:$B$54,N13,$C$5:$C$54)+SUMIF($F$5:$F$54,N13,$G$5:$G$54)) | Q13: =IF(N13="","",SUMIF($B$5:$B$54,N13,$D$5:$D$54)+SUMIF($H$5:$H$54,N13,$I$5:$I$54)) | R13: =IF(N13="","",SUMIF($F$5:$F$54,N13,$G$5:$G$54)) | S13: =IF(N13="","",SUMIF($H$5:$H$54,N13,$I$5:$I$54)) | T13: =IF(N13="","",R13+S13) | U13: =IF(N13="","",MAX(0,SUMIF($B$5:$B$54,N13,$C$5:$C$54)+SUMIF($B$5:$B$54,N13,$D$5:$D$54)-R13-S13)) | V13: =IF(N13="","",MAX(0,SUMIF($B$5:$B$54,N13,$C$5:$C$54)-R13)) | W13: =IF(N13="","",MAX(0,SUMIF($B$5:$B$54,N13,$D$5:$D$54)-S13)) | X13: =IF(N13="","",V13+W13)
A14: Miquelle | B14: L | C14: 0 | D14: 1 | E14: =IF(B14="","",IF(AND(C14>0,D14>0),C14&" Short Sleeve + "&D14&" Long Sleeve",IF(C14>0,C14&" Short Sleeve",IF(D14>0,D14&" Long Sleeve","")))) -> 1 Long Sleeve | F14: L | G14: 1 | I14: 0 | J14: =IF(A14="","",N(G14)+N(I14)) -> 1 | K14: =IF(A14="","",MAX(0,N(C14)+N(D14)-N(G14)-N(I14))) -> 0 | N14: =IF('Size Setup'!A13="","",'Size Setup'!A13) | O14: =IF(N14="","",COUNTIF($B$5:$B$54,N14)+SUMIF($F$5:$F$54,N14,$G$5:$G$54)+SUMIF($H$5:$H$54,N14,$I$5:$I$54)) | P14: =IF(N14="","",SUMIF($B$5:$B$54,N14,$C$5:$C$54)+SUMIF($F$5:$F$54,N14,$G$5:$G$54)) | Q14: =IF(N14="","",SUMIF($B$5:$B$54,N14,$D$5:$D$54)+SUMIF($H$5:$H$54,N14,$I$5:$I$54)) | R14: =IF(N14="","",SUMIF($F$5:$F$54,N14,$G$5:$G$54)) | S14: =IF(N14="","",SUMIF($H$5:$H$54,N14,$I$5:$I$54)) | T14: =IF(N14="","",R14+S14) | U14: =IF(N14="","",MAX(0,SUMIF($B$5:$B$54,N14,$C$5:$C$54)+SUMIF($B$5:$B$54,N14,$D$5:$D$54)-R14-S14)) | V14: =IF(N14="","",MAX(0,SUMIF($B$5:$B$54,N14,$C$5:$C$54)-R14)) | W14: =IF(N14="","",MAX(0,SUMIF($B$5:$B$54,N14,$D$5:$D$54)-S14)) | X14: =IF(N14="","",V14+W14)
A15: Fernando | B15: M | C15: 0 | D15: 1 | E15: =IF(B15="","",IF(AND(C15>0,D15>0),C15&" Short Sleeve + "&D15&" Long Sleeve",IF(C15>0,C15&" Short Sleeve",IF(D15>0,D15&" Long Sleeve","")))) -> 1 Long Sleeve | F15: M | G15: 1 | I15: 0 | J15: =IF(A15="","",N(G15)+N(I15)) -> 1 | K15: =IF(A15="","",MAX(0,N(C15)+N(D15)-N(G15)-N(I15))) -> 0 | N15: =IF('Size Setup'!A14="","",'Size Setup'!A14) | O15: =IF(N15="","",COUNTIF($B$5:$B$54,N15)+SUMIF($F$5:$F$54,N15,$G$5:$G$54)+SUMIF($H$5:$H$54,N15,$I$5:$I$54)) | P15: =IF(N15="","",SUMIF($B$5:$B$54,N15,$C$5:$C$54)+SUMIF($F$5:$F$54,N15,$G$5:$G$54)) | Q15: =IF(N15="","",SUMIF($B$5:$B$54,N15,$D$5:$D$54)+SUMIF($H$5:$H$54,N15,$I$5:$I$54)) | R15: =IF(N15="","",SUMIF($F$5:$F$54,N15,$G$5:$G$54)) | S15: =IF(N15="","",SUMIF($H$5:$H$54,N15,$I$5:$I$54)) | T15: =IF(N15="","",R15+S15) | U15: =IF(N15="","",MAX(0,SUMIF($B$5:$B$54,N15,$C$5:$C$54)+SUMIF($B$5:$B$54,N15,$D$5:$D$54)-R15-S15)) | V15: =IF(N15="","",MAX(0,SUMIF($B$5:$B$54,N15,$C$5:$C$54)-R15)) | W15: =IF(N15="","",MAX(0,SUMIF($B$5:$B$54,N15,$D$5:$D$54)-S15)) | X15: =IF(N15="","",V15+W15)
A16: Joshio | E16: =IF(B16="","",IF(AND(C16>0,D16>0),C16&" Short Sleeve + "&D16&" Long Sleeve",IF(C16>0,C16&" Short Sleeve",IF(D16>0,D16&" Long Sleeve","")))) | H16: L | I16: 1 | J16: =IF(A16="","",N(G16)+N(I16)) -> 1 | K16: =IF(A16="","",MAX(0,N(C16)+N(D16)-N(G16)-N(I16))) -> 0 | N16: =IF('Size Setup'!A15="","",'Size Setup'!A15) | O16: =IF(N16="","",COUNTIF($B$5:$B$54,N16)+SUMIF($F$5:$F$54,N16,$G$5:$G$54)+SUMIF($H$5:$H$54,N16,$I$5:$I$54)) | P16: =IF(N16="","",SUMIF($B$5:$B$54,N16,$C$5:$C$54)+SUMIF($F$5:$F$54,N16,$G$5:$G$54)) | Q16: =IF(N16="","",SUMIF($B$5:$B$54,N16,$D$5:$D$54)+SUMIF($H$5:$H$54,N16,$I$5:$I$54)) | R16: =IF(N16="","",SUMIF($F$5:$F$54,N16,$G$5:$G$54)) | S16: =IF(N16="","",SUMIF($H$5:$H$54,N16,$I$5:$I$54)) | T16: =IF(N16="","",R16+S16) | U16: =IF(N16="","",MAX(0,SUMIF($B$5:$B$54,N16,$C$5:$C$54)+SUMIF($B$5:$B$54,N16,$D$5:$D$54)-R16-S16)) | V16: =IF(N16="","",MAX(0,SUMIF($B$5:$B$54,N16,$C$5:$C$54)-R16)) | W16: =IF(N16="","",MAX(0,SUMIF($B$5:$B$54,N16,$D$5:$D$54)-S16)) | X16: =IF(N16="","",V16+W16)
E17: =IF(B17="","",IF(AND(C17>0,D17>0),C17&" Short Sleeve + "&D17&" Long Sleeve",IF(C17>0,C17&" Short Sleeve",IF(D17>0,D17&" Long Sleeve","")))) | J17: =IF(A17="","",N(G17)+N(I17)) | K17: =IF(A17="","",MAX(0,N(C17)+N(D17)-N(G17)-N(I17))) | N17: =IF('Size Setup'!A16="","",'Size Setup'!A16) | O17: =IF(N17="","",COUNTIF($B$5:$B$54,N17)+SUMIF($F$5:$F$54,N17,$G$5:$G$54)+SUMIF($H$5:$H$54,N17,$I$5:$I$54)) | P17: =IF(N17="","",SUMIF($B$5:$B$54,N17,$C$5:$C$54)+SUMIF($F$5:$F$54,N17,$G$5:$G$54)) | Q17: =IF(N17="","",SUMIF($B$5:$B$54,N17,$D$5:$D$54)+SUMIF($H$5:$H$54,N17,$I$5:$I$54)) | R17: =IF(N17="","",SUMIF($F$5:$F$54,N17,$G$5:$G$54)) | S17: =IF(N17="","",SUMIF($H$5:$H$54,N17,$I$5:$I$54)) | T17: =IF(N17="","",R17+S17) | U17: =IF(N17="","",MAX(0,SUMIF($B$5:$B$54,N17,$C$5:$C$54)+SUMIF($B$5:$B$54,N17,$D$5:$D$54)-R17-S17)) | V17: =IF(N17="","",MAX(0,SUMIF($B$5:$B$54,N17,$C$5:$C$54)-R17)) | W17: =IF(N17="","",MAX(0,SUMIF($B$5:$B$54,N17,$D$5:$D$54)-S17)) | X17: =IF(N17="","",V17+W17)
E18: =IF(B18="","",IF(AND(C18>0,D18>0),C18&" Short Sleeve + "&D18&" Long Sleeve",IF(C18>0,C18&" Short Sleeve",IF(D18>0,D18&" Long Sleeve","")))) | J18: =IF(A18="","",N(G18)+N(I18)) | K18: =IF(A18="","",MAX(0,N(C18)+N(D18)-N(G18)-N(I18))) | O18: =IF(N18="","",COUNTIF($B$5:$B$54,N18)+SUMIF($F$5:$F$54,N18,$G$5:$G$54)+SUMIF($H$5:$H$54,N18,$I$5:$I$54)) | P18: =IF(N18="","",SUMIF($B$5:$B$54,N18,$C$5:$C$54)+SUMIF($F$5:$F$54,N18,$G$5:$G$54)) | Q18: =IF(N18="","",SUMIF($B$5:$B$54,N18,$D$5:$D$54)+SUMIF($H$5:$H$54,N18,$I$5:$I$54)) | R18: =IF(N18="","",SUMIF($F$5:$F$54,N18,$G$5:$G$54)) | S18: =IF(N18="","",SUMIF($H$5:$H$54,N18,$I$5:$I$54)) | T18: =IF(N18="","",R18+S18) | U18: =IF(N18="","",MAX(0,SUMIF($B$5:$B$54,N18,$C$5:$C$54)+SUMIF($B$5:$B$54,N18,$D$5:$D$54)-R18-S18))
E19: =IF(B19="","",IF(AND(C19>0,D19>0),C19&" Short Sleeve + "&D19&" Long Sleeve",IF(C19>0,C19&" Short Sleeve",IF(D19>0,D19&" Long Sleeve","")))) | J19: =IF(A19="","",N(G19)+N(I19)) | K19: =IF(A19="","",MAX(0,N(C19)+N(D19)-N(G19)-N(I19))) | O19: =IF(N19="","",COUNTIF($B$5:$B$54,N19)+SUMIF($F$5:$F$54,N19,$G$5:$G$54)+SUMIF($H$5:$H$54,N19,$I$5:$I$54)) | P19: =IF(N19="","",SUMIF($B$5:$B$54,N19,$C$5:$C$54)+SUMIF($F$5:$F$54,N19,$G$5:$G$54)) | Q19: =IF(N19="","",SUMIF($B$5:$B$54,N19,$D$5:$D$54)+SUMIF($H$5:$H$54,N19,$I$5:$I$54)) | R19: =IF(N19="","",SUMIF($F$5:$F$54,N19,$G$5:$G$54)) | S19: =IF(N19="","",SUMIF($H$5:$H$54,N19,$I$5:$I$54)) | T19: =IF(N19="","",R19+S19) | U19: =IF(N19="","",MAX(0,SUMIF($B$5:$B$54,N19,$C$5:$C$54)+SUMIF($B$5:$B$54,N19,$D$5:$D$54)-R19-S19))
E20: =IF(B20="","",IF(AND(C20>0,D20>0),C20&" Short Sleeve + "&D20&" Long Sleeve",IF(C20>0,C20&" Short Sleeve",IF(D20>0,D20&" Long Sleeve","")))) | J20: =IF(A20="","",N(G20)+N(I20)) | K20: =IF(A20="","",MAX(0,N(C20)+N(D20)-N(G20)-N(I20))) | O20: =IF(N20="","",COUNTIF($B$5:$B$54,N20)+SUMIF($F$5:$F$54,N20,$G$5:$G$54)+SUMIF($H$5:$H$54,N20,$I$5:$I$54)) | P20: =IF(N20="","",SUMIF($B$5:$B$54,N20,$C$5:$C$54)+SUMIF($F$5:$F$54,N20,$G$5:$G$54)) | Q20: =IF(N20="","",SUMIF($B$5:$B$54,N20,$D$5:$D$54)+SUMIF($H$5:$H$54,N20,$I$5:$I$54)) | R20: =IF(N20="","",SUMIF($F$5:$F$54,N20,$G$5:$G$54)) | S20: =IF(N20="","",SUMIF($H$5:$H$54,N20,$I$5:$I$54)) | T20: =IF(N20="","",R20+S20) | U20: =IF(N20="","",MAX(0,SUMIF($B$5:$B$54,N20,$C$5:$C$54)+SUMIF($B$5:$B$54,N20,$D$5:$D$54)-R20-S20))
E21: =IF(B21="","",IF(AND(C21>0,D21>0),C21&" Short Sleeve + "&D21&" Long Sleeve",IF(C21>0,C21&" Short Sleeve",IF(D21>0,D21&" Long Sleeve","")))) | J21: =IF(A21="","",N(G21)+N(I21)) | K21: =IF(A21="","",MAX(0,N(C21)+N(D21)-N(G21)-N(I21))) | O21: =IF(N21="","",COUNTIF($B$5:$B$54,N21)+SUMIF($F$5:$F$54,N21,$G$5:$G$54)+SUMIF($H$5:$H$54,N21,$I$5:$I$54)) | P21: =IF(N21="","",SUMIF($B$5:$B$54,N21,$C$5:$C$54)+SUMIF($F$5:$F$54,N21,$G$5:$G$54)) | Q21: =IF(N21="","",SUMIF($B$5:$B$54,N21,$D$5:$D$54)+SUMIF($H$5:$H$54,N21,$I$5:$I$54)) | R21: =IF(N21="","",SUMIF($F$5:$F$54,N21,$G$5:$G$54)) | S21: =IF(N21="","",SUMIF($H$5:$H$54,N21,$I$5:$I$54)) | T21: =IF(N21="","",R21+S21) | U21: =IF(N21="","",MAX(0,SUMIF($B$5:$B$54,N21,$C$5:$C$54)+SUMIF($B$5:$B$54,N21,$D$5:$D$54)-R21-S21))
E22: =IF(B22="","",IF(AND(C22>0,D22>0),C22&" Short Sleeve + "&D22&" Long Sleeve",IF(C22>0,C22&" Short Sleeve",IF(D22>0,D22&" Long Sleeve","")))) | J22: =IF(A22="","",N(G22)+N(I22)) | K22: =IF(A22="","",MAX(0,N(C22)+N(D22)-N(G22)-N(I22))) | O22: =IF(N22="","",COUNTIF($B$5:$B$54,N22)+SUMIF($F$5:$F$54,N22,$G$5:$G$54)+SUMIF($H$5:$H$54,N22,$I$5:$I$54)) | P22: =IF(N22="","",SUMIF($B$5:$B$54,N22,$C$5:$C$54)+SUMIF($F$5:$F$54,N22,$G$5:$G$54)) | Q22: =IF(N22="","",SUMIF($B$5:$B$54,N22,$D$5:$D$54)+SUMIF($H$5:$H$54,N22,$I$5:$I$54)) | R22: =IF(N22="","",SUMIF($F$5:$F$54,N22,$G$5:$G$54)) | S22: =IF(N22="","",SUMIF($H$5:$H$54,N22,$I$5:$I$54)) | T22: =IF(N22="","",R22+S22) | U22: =IF(N22="","",MAX(0,SUMIF($B$5:$B$54,N22,$C$5:$C$54)+SUMIF($B$5:$B$54,N22,$D$5:$D$54)-R22-S22))
E23: =IF(B23="","",IF(AND(C23>0,D23>0),C23&" Short Sleeve + "&D23&" Long Sleeve",IF(C23>0,C23&" Short Sleeve",IF(D23>0,D23&" Long Sleeve","")))) | J23: =IF(A23="","",N(G23)+N(I23)) | K23: =IF(A23="","",MAX(0,N(C23)+N(D23)-N(G23)-N(I23))) | O23: =IF(N23="","",COUNTIF($B$5:$B$54,N23)+SUMIF($F$5:$F$54,N23,$G$5:$G$54)+SUMIF($H$5:$H$54,N23,$I$5:$I$54)) | P23: =IF(N23="","",SUMIF($B$5:$B$54,N23,$C$5:$C$54)+SUMIF($F$5:$F$54,N23,$G$5:$G$54)) | Q23: =IF(N23="","",SUMIF($B$5:$B$54,N23,$D$5:$D$54)+SUMIF($H$5:$H$54,N23,$I$5:$I$54)) | R23: =IF(N23="","",SUMIF($F$5:$F$54,N23,$G$5:$G$54)) | S23: =IF(N23="","",SUMIF($H$5:$H$54,N23,$I$5:$I$54)) | T23: =IF(N23="","",R23+S23) | U23: =IF(N23="","",MAX(0,SUMIF($B$5:$B$54,N23,$C$5:$C$54)+SUMIF($B$5:$B$54,N23,$D$5:$D$54)-R23-S23))
E24: =IF(B24="","",IF(AND(C24>0,D24>0),C24&" Short Sleeve + "&D24&" Long Sleeve",IF(C24>0,C24&" Short Sleeve",IF(D24>0,D24&" Long Sleeve","")))) | J24: =IF(A24="","",N(G24)+N(I24)) | K24: =IF(A24="","",MAX(0,N(C24)+N(D24)-N(G24)-N(I24))) | O24: =IF(N24="","",COUNTIF($B$5:$B$54,N24)+SUMIF($F$5:$F$54,N24,$G$5:$G$54)+SUMIF($H$5:$H$54,N24,$I$5:$I$54)) | P24: =IF(N24="","",SUMIF($B$5:$B$54,N24,$C$5:$C$54)+SUMIF($F$5:$F$54,N24,$G$5:$G$54)) | Q24: =IF(N24="","",SUMIF($B$5:$B$54,N24,$D$5:$D$54)+SUMIF($H$5:$H$54,N24,$I$5:$I$54)) | R24: =IF(N24="","",SUMIF($F$5:$F$54,N24,$G$5:$G$54)) | S24: =IF(N24="","",SUMIF($H$5:$H$54,N24,$I$5:$I$54)) | T24: =IF(N24="","",R24+S24) | U24: =IF(N24="","",MAX(0,SUMIF($B$5:$B$54,N24,$C$5:$C$54)+SUMIF($B$5:$B$54,N24,$D$5:$D$54)-R24-S24))
E25: =IF(B25="","",IF(AND(C25>0,D25>0),C25&" Short Sleeve + "&D25&" Long Sleeve",IF(C25>0,C25&" Short Sleeve",IF(D25>0,D25&" Long Sleeve","")))) | J25: =IF(A25="","",N(G25)+N(I25)) | K25: =IF(A25="","",MAX(0,N(C25)+N(D25)-N(G25)-N(I25))) | O25: =IF(N25="","",COUNTIF($B$5:$B$54,N25)+SUMIF($F$5:$F$54,N25,$G$5:$G$54)+SUMIF($H$5:$H$54,N25,$I$5:$I$54)) | P25: =IF(N25="","",SUMIF($B$5:$B$54,N25,$C$5:$C$54)+SUMIF($F$5:$F$54,N25,$G$5:$G$54)) | Q25: =IF(N25="","",SUMIF($B$5:$B$54,N25,$D$5:$D$54)+SUMIF($H$5:$H$54,N25,$I$5:$I$54)) | R25: =IF(N25="","",SUMIF($F$5:$F$54,N25,$G$5:$G$54)) | S25: =IF(N25="","",SUMIF($H$5:$H$54,N25,$I$5:$I$54)) | T25: =IF(N25="","",R25+S25) | U25: =IF(N25="","",MAX(0,SUMIF($B$5:$B$54,N25,$C$5:$C$54)+SUMIF($B$5:$B$54,N25,$D$5:$D$54)-R25-S25))
E26: =IF(B26="","",IF(AND(C26>0,D26>0),C26&" Short Sleeve + "&D26&" Long Sleeve",IF(C26>0,C26&" Short Sleeve",IF(D26>0,D26&" Long Sleeve","")))) | J26: =IF(A26="","",N(G26)+N(I26)) | K26: =IF(A26="","",MAX(0,N(C26)+N(D26)-N(G26)-N(I26))) | O26: =IF(N26="","",COUNTIF($B$5:$B$54,N26)+SUMIF($F$5:$F$54,N26,$G$5:$G$54)+SUMIF($H$5:$H$54,N26,$I$5:$I$54)) | P26: =IF(N26="","",SUMIF($B$5:$B$54,N26,$C$5:$C$54)+SUMIF($F$5:$F$54,N26,$G$5:$G$54)) | Q26: =IF(N26="","",SUMIF($B$5:$B$54,N26,$D$5:$D$54)+SUMIF($H$5:$H$54,N26,$I$5:$I$54)) | R26: =IF(N26="","",SUMIF($F$5:$F$54,N26,$G$5:$G$54)) | S26: =IF(N26="","",SUMIF($H$5:$H$54,N26,$I$5:$I$54)) | T26: =IF(N26="","",R26+S26) | U26: =IF(N26="","",MAX(0,SUMIF($B$5:$B$54,N26,$C$5:$C$54)+SUMIF($B$5:$B$54,N26,$D$5:$D$54)-R26-S26))
E27: =IF(B27="","",IF(AND(C27>0,D27>0),C27&" Short Sleeve + "&D27&" Long Sleeve",IF(C27>0,C27&" Short Sleeve",IF(D27>0,D27&" Long Sleeve","")))) | J27: =IF(A27="","",N(G27)+N(I27)) | K27: =IF(A27="","",MAX(0,N(C27)+N(D27)-N(G27)-N(I27))) | O27: =IF(N27="","",COUNTIF($B$5:$B$54,N27)+SUMIF($F$5:$F$54,N27,$G$5:$G$54)+SUMIF($H$5:$H$54,N27,$I$5:$I$54)) | P27: =IF(N27="","",SUMIF($B$5:$B$54,N27,$C$5:$C$54)+SUMIF($F$5:$F$54,N27,$G$5:$G$54)) | Q27: =IF(N27="","",SUMIF($B$5:$B$54,N27,$D$5:$D$54)+SUMIF($H$5:$H$54,N27,$I$5:$I$54)) | R27: =IF(N27="","",SUMIF($F$5:$F$54,N27,$G$5:$G$54)) | S27: =IF(N27="","",SUMIF($H$5:$H$54,N27,$I$5:$I$54)) | T27: =IF(N27="","",R27+S27) | U27: =IF(N27="","",MAX(0,SUMIF($B$5:$B$54,N27,$C$5:$C$54)+SUMIF($B$5:$B$54,N27,$D$5:$D$54)-R27-S27))
E28: =IF(B28="","",IF(AND(C28>0,D28>0),C28&" Short Sleeve + "&D28&" Long Sleeve",IF(C28>0,C28&" Short Sleeve",IF(D28>0,D28&" Long Sleeve","")))) | J28: =IF(A28="","",N(G28)+N(I28)) | K28: =IF(A28="","",MAX(0,N(C28)+N(D28)-N(G28)-N(I28))) | O28: =IF(N28="","",COUNTIF($B$5:$B$54,N28)+SUMIF($F$5:$F$54,N28,$G$5:$G$54)+SUMIF($H$5:$H$54,N28,$I$5:$I$54)) | P28: =IF(N28="","",SUMIF($B$5:$B$54,N28,$C$5:$C$54)+SUMIF($F$5:$F$54,N28,$G$5:$G$54)) | Q28: =IF(N28="","",SUMIF($B$5:$B$54,N28,$D$5:$D$54)+SUMIF($H$5:$H$54,N28,$I$5:$I$54)) | R28: =IF(N28="","",SUMIF($F$5:$F$54,N28,$G$5:$G$54)) | S28: =IF(N28="","",SUMIF($H$5:$H$54,N28,$I$5:$I$54)) | T28: =IF(N28="","",R28+S28) | U28: =IF(N28="","",MAX(0,SUMIF($B$5:$B$54,N28,$C$5:$C$54)+SUMIF($B$5:$B$54,N28,$D$5:$D$54)-R28-S28))
E29: =IF(B29="","",IF(AND(C29>0,D29>0),C29&" Short Sleeve + "&D29&" Long Sleeve",IF(C29>0,C29&" Short Sleeve",IF(D29>0,D29&" Long Sleeve","")))) | J29: =IF(A29="","",N(G29)+N(I29)) | K29: =IF(A29="","",MAX(0,N(C29)+N(D29)-N(G29)-N(I29))) | O29: =IF(N29="","",COUNTIF($B$5:$B$54,N29)+SUMIF($F$5:$F$54,N29,$G$5:$G$54)+SUMIF($H$5:$H$54,N29,$I$5:$I$54)) | P29: =IF(N29="","",SUMIF($B$5:$B$54,N29,$C$5:$C$54)+SUMIF($F$5:$F$54,N29,$G$5:$G$54)) | Q29: =IF(N29="","",SUMIF($B$5:$B$54,N29,$D$5:$D$54)+SUMIF($H$5:$H$54,N29,$I$5:$I$54)) | R29: =IF(N29="","",SUMIF($F$5:$F$54,N29,$G$5:$G$54)) | S29: =IF(N29="","",SUMIF($H$5:$H$54,N29,$I$5:$I$54)) | T29: =IF(N29="","",R29+S29) | U29: =IF(N29="","",MAX(0,SUMIF($B$5:$B$54,N29,$C$5:$C$54)+SUMIF($B$5:$B$54,N29,$D$5:$D$54)-R29-S29))
... E33: =IF(B33="","",IF(AND(C33>0,D33>0),C33&" Short Sleeve + "&D33&" Long Sleeve",IF(C33>0,C33&" Short Sleeve",IF(D33>0,D33&" Long Sleeve","")))) | J33: =IF(A33="","",N(G33)+N(I33)) | K33: =IF(A33="","",MAX(0,N(C33)+N(D33)-N(G33)-N(I33))) | O33: =IF(N33="","",COUNTIF($B$5:$B$54,N33)+SUMIF($F$5:$F$54,N33,$G$5:$G$54)+SUMIF($H$5:$H$54,N33,$I$5:$I$54)) | P33: =IF(N33="","",SUMIF($B$5:$B$54,N33,$C$5:$C$54)+SUMIF($F$5:$F$54,N33,$G$5:$G$54)) | Q33: =IF(N33="","",SUMIF($B$5:$B$54,N33,$D$5:$D$54)+SUMIF($H$5:$H$54,N33,$I$5:$I$54)) | R33: =IF(N33="","",SUMIF($F$5:$F$54,N33,$G$5:$G$54)) | S33: =IF(N33="","",SUMIF($H$5:$H$54,N33,$I$5:$I$54)) | T33: =IF(N33="","",R33+S33) | U33: =IF(N33="","",MAX(0,SUMIF($B$5:$B$54,N33,$C$5:$C$54)+SUMIF($B$5:$B$54,N33,$D$5:$D$54)-R33-S33))
E34: =IF(B34="","",IF(AND(C34>0,D34>0),C34&" Short Sleeve + "&D34&" Long Sleeve",IF(C34>0,C34&" Short Sleeve",IF(D34>0,D34&" Long Sleeve","")))) | J34: =IF(A34="","",N(G34)+N(I34)) | K34: =IF(A34="","",MAX(0,N(C34)+N(D34)-N(G34)-N(I34)))
E35: =IF(B35="","",IF(AND(C35>0,D35>0),C35&" Short Sleeve + "&D35&" Long Sleeve",IF(C35>0,C35&" Short Sleeve",IF(D35>0,D35&" Long Sleeve","")))) | J35: =IF(A35="","",N(G35)+N(I35)) | K35: =IF(A35="","",MAX(0,N(C35)+N(D35)-N(G35)-N(I35))) | N35: TOTAL | O35: =COUNTIF($B$5:$B$54,"<>")+SUM($G$5:$G$54)+SUM($I$5:$I$54) -> 16 | P35: =SUM($C$5:$C$54)+SUM($G$5:$G$54) -> 25 | Q35: =SUM($D$5:$D$54)+SUM($I$5:$I$54) -> 9 | R35: =SUM($G$5:$G$54) -> 3 | S35: =SUM($I$5:$I$54) -> 2 | T35: =SUM($G$5:$G$54)+SUM($I$5:$I$54) -> 5 | U35: =SUM($C$5:$C$54)+SUM($D$5:$D$54)-SUM($G$5:$G$54)-SUM($I$5:$I$54) -> 24 | V35: =SUM(V4:V17) -> 19 | W35: =SUM(W4:W17) -> 5 | X35: =SUM(X4:X17) -> 24
E36: =IF(B36="","",IF(AND(C36>0,D36>0),C36&" Short Sleeve + "&D36&" Long Sleeve",IF(C36>0,C36&" Short Sleeve",IF(D36>0,D36&" Long Sleeve","")))) | J36: =IF(A36="","",N(G36)+N(I36)) | K36: =IF(A36="","",MAX(0,N(C36)+N(D36)-N(G36)-N(I36)))
E37: =IF(B37="","",IF(AND(C37>0,D37>0),C37&" Short Sleeve + "&D37&" Long Sleeve",IF(C37>0,C37&" Short Sleeve",IF(D37>0,D37&" Long Sleeve","")))) | J37: =IF(A37="","",N(G37)+N(I37)) | K37: =IF(A37="","",MAX(0,N(C37)+N(D37)-N(G37)-N(I37))) | N37: Original Shirts | P37: Total Returned / Surplus | R37: Total With Returns | T37: Net Issued | V37: TOTAL POLOS TO ACTUALLY ORDER
E38: =IF(B38="","",IF(AND(C38>0,D38>0),C38&" Short Sleeve + "&D38&" Long Sleeve",IF(C38>0,C38&" Short Sleeve",IF(D38>0,D38&" Long Sleeve","")))) | J38: =IF(A38="","",N(G38)+N(I38)) | K38: =IF(A38="","",MAX(0,N(C38)+N(D38)-N(G38)-N(I38))) | N38: =SUM($C$5:$C$54)+SUM($D$5:$D$54) -> 29 | P38: =SUM($G$5:$G$54)+SUM($I$5:$I$54) -> 5 | R38: =SUM($C$5:$C$54)+SUM($D$5:$D$54)+SUM($G$5:$G$54)+SUM($I$5:$I$54) -> 34 | T38: =SUM($C$5:$C$54)+SUM($D$5:$D$54)-SUM($G$5:$G$54)-SUM($I$5:$I$54) -> 24 | V38: =X35 -> 24
E39: =IF(B39="","",IF(AND(C39>0,D39>0),C39&" Short Sleeve + "&D39&" Long Sleeve",IF(C39>0,C39&" Short Sleeve",IF(D39>0,D39&" Long Sleeve","")))) | J39: =IF(A39="","",N(G39)+N(I39)) | K39: =IF(A39="","",MAX(0,N(C39)+N(D39)-N(G39)-N(I39)))
E40: =IF(B40="","",IF(AND(C40>0,D40>0),C40&" Short Sleeve + "&D40&" Long Sleeve",IF(C40>0,C40&" Short Sleeve",IF(D40>0,D40&" Long Sleeve","")))) | J40: =IF(A40="","",N(G40)+N(I40)) | K40: =IF(A40="","",MAX(0,N(C40)+N(D40)-N(G40)-N(I40)))
E41: =IF(B41="","",IF(AND(C41>0,D41>0),C41&" Short Sleeve + "&D41&" Long Sleeve",IF(C41>0,C41&" Short Sleeve",IF(D41>0,D41&" Long Sleeve","")))) | J41: =IF(A41="","",N(G41)+N(I41)) | K41: =IF(A41="","",MAX(0,N(C41)+N(D41)-N(G41)-N(I41)))
E42: =IF(B42="","",IF(AND(C42>0,D42>0),C42&" Short Sleeve + "&D42&" Long Sleeve",IF(C42>0,C42&" Short Sleeve",IF(D42>0,D42&" Long Sleeve","")))) | J42: =IF(A42="","",N(G42)+N(I42)) | K42: =IF(A42="","",MAX(0,N(C42)+N(D42)-N(G42)-N(I42)))
E43: =IF(B43="","",IF(AND(C43>0,D43>0),C43&" Short Sleeve + "&D43&" Long Sleeve",IF(C43>0,C43&" Short Sleeve",IF(D43>0,D43&" Long Sleeve","")))) | J43: =IF(A43="","",N(G43)+N(I43)) | K43: =IF(A43="","",MAX(0,N(C43)+N(D43)-N(G43)-N(I43)))
...

Sheet Size Setup
A1: Order & Return Size Setup
A2: Polo Size | B2: Active | C2: Notes | E2: How to use
A3: M | B3: Yes | E3: This is the fixed master size list used by all size dropdowns.
A4: L | B4: Yes | E4: Order Size uses only the sizes listed in A3:A16.
A5: XL | B5: Yes | E5: Return Short Size uses only the sizes listed in A3:A16.
A6: W S | B6: Yes | E6: Return Long Size uses only the sizes listed in A3:A16.
B7: Yes | E7: The master list does not expand automatically.
B8: Yes
B9: Yes
B10: Yes
B11: Yes
B12: Yes
B13: Yes
B14: Yes
B15: Yes
B16: Yes
