Workbook

Sheet Monthly Scorecard
A1: Stefanini Field Services - Monthly Performance Scorecard
A2: Year | B2: Month | C2: Team Leader | D2: Tech Name | E2: Shift | F2: Volume | G2: Incidents Completed | H2: Tasks Completed | I2: SLA Compliance | J2: Interactions Completed | K2: CSAT | L2: Attendance | M2: Stale Tasks | N2: KB Articles | O2: Recognitions | P2: Missing Epic Assets | Q2: Incident Score | R2: Task Score | S2: SLA Score | T2: Interaction Score | U2: CSAT Score | V2: Attendance Score | W2: Stale Score | X2: KB Score | Y2: Recognition Score | Z2: Epic Assets Score | AA2: Calculated Score | AB2: Calculated Rating | AC2: Entry Status | AD2: Manual Final Score | AE2: Manual Rating Override | AF2: Final Score | AG2: Final Rating | AH2: Lookup Key
A3: 2026 | B3: January | C3: Joshio Flores | D3: Carly Huber | F3: =IF(E3="","",IFERROR(VLOOKUP(E3,'Input & Settings'!$F$5:$G$10,2,FALSE),"")) | Q3: =IF(G3="","",IFERROR(MIN(100,G3/'Input & Settings'!$B$5*100),"")) | R3: =IF(H3="","",IFERROR(MIN(100,H3/'Input & Settings'!$B$6*100),"")) | S3: =IF(I3="","",IFERROR(MIN(100,I3/'Input & Settings'!$B$7*100),"")) | T3: =IF(J3="","",IFERROR(MIN(100,J3/'Input & Settings'!$B$8*100),"")) | U3: =IF(K3="","",IFERROR(MIN(100,K3/'Input & Settings'!$B$9*100),"")) | V3: =IF(L3="","",IFERROR(MIN(100,L3/'Input & Settings'!$B$10*100),"")) | W3: =IF(M3="","",IFERROR(IF(M3<='Input & Settings'!$B$11,100,MAX(0,100-(M3-'Input & Settings'!$B$11)*20)),"")) | X3: =IF(N3="","",IFERROR(MIN(100,N3/'Input & Settings'!$B$12*100),"")) | Y3: =IF(O3="","",IFERROR(MIN(100,O3/'Input & Settings'!$B$13*100),"")) | Z3: =IF(P3="","",IFERROR(IF(P3<='Input & Settings'!$B$14,100,MAX(0,100-(P3-'Input & Settings'!$B$14)*20)),"")) | AA3: =IF(COUNTA(G3:P3)=0,"",ROUND(Q3*'Input & Settings'!$C$5+R3*'Input & Settings'!$C$6+S3*'Input & Settings'!$C$7+T3*'Input & Settings'!$C$8+U3*'Input & Settings'!$C$9+V3*'Input & Settings'!$C$10+W3*'Input & Settings'!$C$11+X3*'Input & Settings'!$C$12+Y3*'Input & Settings'!$C$13+Z3*'Input & Settings'!$C$14,1)) | AB3: =IF(OR(AA3="",E3=""),"",IFERROR(IF(AA3>=VLOOKUP(E3,'Input & Settings'!$F$5:$K$10,3,FALSE),"Outstanding",IF(AA3>=VLOOKUP(E3,'Input & Settings'!$F$5:$K$10,4,FALSE),"Exceeds Expectations",IF(AA3>=VLOOKUP(E3,'Input & Settings'!$F$5:$K$10,5,FALSE),"Meets Expectations",IF(AA3>=VLOOKUP(E3,'Input & Settings'!$F$5:$K$10,6,FALSE),"Needs Improvement","Performance Improvement Required")))),"")) | AC3: =IF(COUNTA(G3:P3)+COUNTA(AD3:AE3)>0,"Entered","") | AF3: =IF(AD3<>"",AD3,AA3) | AG3: =IF(AE3<>"",AE3,AB3) | AH3: =D3&"|"&B3 -> Carly Huber|January
A4: 2026 | B4: January | C4: Joshio Flores | D4: Julian Grier | F4: =IF(E4="","",IFERROR(VLOOKUP(E4,'Input & Settings'!$F$5:$G$10,2,FALSE),"")) | Q4: =IF(G4="","",IFERROR(MIN(100,G4/'Input & Settings'!$B$5*100),"")) | R4: =IF(H4="","",IFERROR(MIN(100,H4/'Input & Settings'!$B$6*100),"")) | S4: =IF(I4="","",IFERROR(MIN(100,I4/'Input & Settings'!$B$7*100),"")) | T4: =IF(J4="","",IFERROR(MIN(100,J4/'Input & Settings'!$B$8*100),"")) | U4: =IF(K4="","",IFERROR(MIN(100,K4/'Input & Settings'!$B$9*100),"")) | V4: =IF(L4="","",IFERROR(MIN(100,L4/'Input & Settings'!$B$10*100),"")) | W4: =IF(M4="","",IFERROR(IF(M4<='Input & Settings'!$B$11,100,MAX(0,100-(M4-'Input & Settings'!$B$11)*20)),"")) | X4: =IF(N4="","",IFERROR(MIN(100,N4/'Input & Settings'!$B$12*100),"")) | Y4: =IF(O4="","",IFERROR(MIN(100,O4/'Input & Settings'!$B$13*100),"")) | Z4: =IF(P4="","",IFERROR(IF(P4<='Input & Settings'!$B$14,100,MAX(0,100-(P4-'Input & Settings'!$B$14)*20)),"")) | AA4: =IF(COUNTA(G4:P4)=0,"",ROUND(Q4*'Input & Settings'!$C$5+R4*'Input & Settings'!$C$6+S4*'Input & Settings'!$C$7+T4*'Input & Settings'!$C$8+U4*'Input & Settings'!$C$9+V4*'Input & Settings'!$C$10+W4*'Input & Settings'!$C$11+X4*'Input & Settings'!$C$12+Y4*'Input & Settings'!$C$13+Z4*'Input & Settings'!$C$14,1)) | AB4: =IF(OR(AA4="",E4=""),"",IFERROR(IF(AA4>=VLOOKUP(E4,'Input & Settings'!$F$5:$K$10,3,FALSE),"Outstanding",IF(AA4>=VLOOKUP(E4,'Input & Settings'!$F$5:$K$10,4,FALSE),"Exceeds Expectations",IF(AA4>=VLOOKUP(E4,'Input & Settings'!$F$5:$K$10,5,FALSE),"Meets Expectations",IF(AA4>=VLOOKUP(E4,'Input & Settings'!$F$5:$K$10,6,FALSE),"Needs Improvement","Performance Improvement Required")))),"")) | AC4: =IF(COUNTA(G4:P4)+COUNTA(AD4:AE4)>0,"Entered","") | AF4: =IF(AD4<>"",AD4,AA4) | AG4: =IF(AE4<>"",AE4,AB4) | AH4: =D4&"|"&B4 -> Julian Grier|January
A5: 2026 | B5: January | C5: Joshio Flores | D5: Jorge Lopez | F5: =IF(E5="","",IFERROR(VLOOKUP(E5,'Input & Settings'!$F$5:$G$10,2,FALSE),"")) | Q5: =IF(G5="","",IFERROR(MIN(100,G5/'Input & Settings'!$B$5*100),"")) | R5: =IF(H5="","",IFERROR(MIN(100,H5/'Input & Settings'!$B$6*100),"")) | S5: =IF(I5="","",IFERROR(MIN(100,I5/'Input & Settings'!$B$7*100),"")) | T5: =IF(J5="","",IFERROR(MIN(100,J5/'Input & Settings'!$B$8*100),"")) | U5: =IF(K5="","",IFERROR(MIN(100,K5/'Input & Settings'!$B$9*100),"")) | V5: =IF(L5="","",IFERROR(MIN(100,L5/'Input & Settings'!$B$10*100),"")) | W5: =IF(M5="","",IFERROR(IF(M5<='Input & Settings'!$B$11,100,MAX(0,100-(M5-'Input & Settings'!$B$11)*20)),"")) | X5: =IF(N5="","",IFERROR(MIN(100,N5/'Input & Settings'!$B$12*100),"")) | Y5: =IF(O5="","",IFERROR(MIN(100,O5/'Input & Settings'!$B$13*100),"")) | Z5: =IF(P5="","",IFERROR(IF(P5<='Input & Settings'!$B$14,100,MAX(0,100-(P5-'Input & Settings'!$B$14)*20)),"")) | AA5: =IF(COUNTA(G5:P5)=0,"",ROUND(Q5*'Input & Settings'!$C$5+R5*'Input & Settings'!$C$6+S5*'Input & Settings'!$C$7+T5*'Input & Settings'!$C$8+U5*'Input & Settings'!$C$9+V5*'Input & Settings'!$C$10+W5*'Input & Settings'!$C$11+X5*'Input & Settings'!$C$12+Y5*'Input & Settings'!$C$13+Z5*'Input & Settings'!$C$14,1)) | AB5: =IF(OR(AA5="",E5=""),"",IFERROR(IF(AA5>=VLOOKUP(E5,'Input & Settings'!$F$5:$K$10,3,FALSE),"Outstanding",IF(AA5>=VLOOKUP(E5,'Input & Settings'!$F$5:$K$10,4,FALSE),"Exceeds Expectations",IF(AA5>=VLOOKUP(E5,'Input & Settings'!$F$5:$K$10,5,FALSE),"Meets Expectations",IF(AA5>=VLOOKUP(E5,'Input & Settings'!$F$5:$K$10,6,FALSE),"Needs Improvement","Performance Improvement Required")))),"")) | AC5: =IF(COUNTA(G5:P5)+COUNTA(AD5:AE5)>0,"Entered","") | AF5: =IF(AD5<>"",AD5,AA5) | AG5: =IF(AE5<>"",AE5,AB5) | AH5: =D5&"|"&B5 -> Jorge Lopez|January
A6: 2026 | B6: January | C6: Joshio Flores | D6: Juan Pablo Pique Buil (JP) | F6: =IF(E6="","",IFERROR(VLOOKUP(E6,'Input & Settings'!$F$5:$G$10,2,FALSE),"")) | Q6: =IF(G6="","",IFERROR(MIN(100,G6/'Input & Settings'!$B$5*100),"")) | R6: =IF(H6="","",IFERROR(MIN(100,H6/'Input & Settings'!$B$6*100),"")) | S6: =IF(I6="","",IFERROR(MIN(100,I6/'Input & Settings'!$B$7*100),"")) | T6: =IF(J6="","",IFERROR(MIN(100,J6/'Input & Settings'!$B$8*100),"")) | U6: =IF(K6="","",IFERROR(MIN(100,K6/'Input & Settings'!$B$9*100),"")) | V6: =IF(L6="","",IFERROR(MIN(100,L6/'Input & Settings'!$B$10*100),"")) | W6: =IF(M6="","",IFERROR(IF(M6<='Input & Settings'!$B$11,100,MAX(0,100-(M6-'Input & Settings'!$B$11)*20)),"")) | X6: =IF(N6="","",IFERROR(MIN(100,N6/'Input & Settings'!$B$12*100),"")) | Y6: =IF(O6="","",IFERROR(MIN(100,O6/'Input & Settings'!$B$13*100),"")) | Z6: =IF(P6="","",IFERROR(IF(P6<='Input & Settings'!$B$14,100,MAX(0,100-(P6-'Input & Settings'!$B$14)*20)),"")) | AA6: =IF(COUNTA(G6:P6)=0,"",ROUND(Q6*'Input & Settings'!$C$5+R6*'Input & Settings'!$C$6+S6*'Input & Settings'!$C$7+T6*'Input & Settings'!$C$8+U6*'Input & Settings'!$C$9+V6*'Input & Settings'!$C$10+W6*'Input & Settings'!$C$11+X6*'Input & Settings'!$C$12+Y6*'Input & Settings'!$C$13+Z6*'Input & Settings'!$C$14,1)) | AB6: =IF(OR(AA6="",E6=""),"",IFERROR(IF(AA6>=VLOOKUP(E6,'Input & Settings'!$F$5:$K$10,3,FALSE),"Outstanding",IF(AA6>=VLOOKUP(E6,'Input & Settings'!$F$5:$K$10,4,FALSE),"Exceeds Expectations",IF(AA6>=VLOOKUP(E6,'Input & Settings'!$F$5:$K$10,5,FALSE),"Meets Expectations",IF(AA6>=VLOOKUP(E6,'Input & Settings'!$F$5:$K$10,6,FALSE),"Needs Improvement","Performance Improvement Required")))),"")) | AC6: =IF(COUNTA(G6:P6)+COUNTA(AD6:AE6)>0,"Entered","") | AF6: =IF(AD6<>"",AD6,AA6) | AG6: =IF(AE6<>"",AE6,AB6) | AH6: =D6&"|"&B6 -> Juan Pablo Pique Buil (JP)|January
A7: 2026 | B7: January | C7: Joshio Flores | D7: Peter Gonzalez | F7: =IF(E7="","",IFERROR(VLOOKUP(E7,'Input & Settings'!$F$5:$G$10,2,FALSE),"")) | Q7: =IF(G7="","",IFERROR(MIN(100,G7/'Input & Settings'!$B$5*100),"")) | R7: =IF(H7="","",IFERROR(MIN(100,H7/'Input & Settings'!$B$6*100),"")) | S7: =IF(I7="","",IFERROR(MIN(100,I7/'Input & Settings'!$B$7*100),"")) | T7: =IF(J7="","",IFERROR(MIN(100,J7/'Input & Settings'!$B$8*100),"")) | U7: =IF(K7="","",IFERROR(MIN(100,K7/'Input & Settings'!$B$9*100),"")) | V7: =IF(L7="","",IFERROR(MIN(100,L7/'Input & Settings'!$B$10*100),"")) | W7: =IF(M7="","",IFERROR(IF(M7<='Input & Settings'!$B$11,100,MAX(0,100-(M7-'Input & Settings'!$B$11)*20)),"")) | X7: =IF(N7="","",IFERROR(MIN(100,N7/'Input & Settings'!$B$12*100),"")) | Y7: =IF(O7="","",IFERROR(MIN(100,O7/'Input & Settings'!$B$13*100),"")) | Z7: =IF(P7="","",IFERROR(IF(P7<='Input & Settings'!$B$14,100,MAX(0,100-(P7-'Input & Settings'!$B$14)*20)),"")) | AA7: =IF(COUNTA(G7:P7)=0,"",ROUND(Q7*'Input & Settings'!$C$5+R7*'Input & Settings'!$C$6+S7*'Input & Settings'!$C$7+T7*'Input & Settings'!$C$8+U7*'Input & Settings'!$C$9+V7*'Input & Settings'!$C$10+W7*'Input & Settings'!$C$11+X7*'Input & Settings'!$C$12+Y7*'Input & Settings'!$C$13+Z7*'Input & Settings'!$C$14,1)) | AB7: =IF(OR(AA7="",E7=""),"",IFERROR(IF(AA7>=VLOOKUP(E7,'Input & Settings'!$F$5:$K$10,3,FALSE),"Outstanding",IF(AA7>=VLOOKUP(E7,'Input & Settings'!$F$5:$K$10,4,FALSE),"Exceeds Expectations",IF(AA7>=VLOOKUP(E7,'Input & Settings'!$F$5:$K$10,5,FALSE),"Meets Expectations",IF(AA7>=VLOOKUP(E7,'Input & Settings'!$F$5:$K$10,6,FALSE),"Needs Improvement","Performance Improvement Required")))),"")) | AC7: =IF(COUNTA(G7:P7)+COUNTA(AD7:AE7)>0,"Entered","") | AF7: =IF(AD7<>"",AD7,AA7) | AG7: =IF(AE7<>"",AE7,AB7) | AH7: =D7&"|"&B7 -> Peter Gonzalez|January
A8: 2026 | B8: January | C8: Joshio Flores | D8: Dennis Hartling | F8: =IF(E8="","",IFERROR(VLOOKUP(E8,'Input & Settings'!$F$5:$G$10,2,FALSE),"")) | Q8: =IF(G8="","",IFERROR(MIN(100,G8/'Input & Settings'!$B$5*100),"")) | R8: =IF(H8="","",IFERROR(MIN(100,H8/'Input & Settings'!$B$6*100),"")) | S8: =IF(I8="","",IFERROR(MIN(100,I8/'Input & Settings'!$B$7*100),"")) | T8: =IF(J8="","",IFERROR(MIN(100,J8/'Input & Settings'!$B$8*100),"")) | U8: =IF(K8="","",IFERROR(MIN(100,K8/'Input & Settings'!$B$9*100),"")) | V8: =IF(L8="","",IFERROR(MIN(100,L8/'Input & Settings'!$B$10*100),"")) | W8: =IF(M8="","",IFERROR(IF(M8<='Input & Settings'!$B$11,100,MAX(0,100-(M8-'Input & Settings'!$B$11)*20)),"")) | X8: =IF(N8="","",IFERROR(MIN(100,N8/'Input & Settings'!$B$12*100),"")) | Y8: =IF(O8="","",IFERROR(MIN(100,O8/'Input & Settings'!$B$13*100),"")) | Z8: =IF(P8="","",IFERROR(IF(P8<='Input & Settings'!$B$14,100,MAX(0,100-(P8-'Input & Settings'!$B$14)*20)),"")) | AA8: =IF(COUNTA(G8:P8)=0,"",ROUND(Q8*'Input & Settings'!$C$5+R8*'Input & Settings'!$C$6+S8*'Input & Settings'!$C$7+T8*'Input & Settings'!$C$8+U8*'Input & Settings'!$C$9+V8*'Input & Settings'!$C$10+W8*'Input & Settings'!$C$11+X8*'Input & Settings'!$C$12+Y8*'Input & Settings'!$C$13+Z8*'Input & Settings'!$C$14,1)) | AB8: =IF(OR(AA8="",E8=""),"",IFERROR(IF(AA8>=VLOOKUP(E8,'Input & Settings'!$F$5:$K$10,3,FALSE),"Outstanding",IF(AA8>=VLOOKUP(E8,'Input & Settings'!$F$5:$K$10,4,FALSE),"Exceeds Expectations",IF(AA8>=VLOOKUP(E8,'Input & Settings'!$F$5:$K$10,5,FALSE),"Meets Expectations",IF(AA8>=VLOOKUP(E8,'Input & Settings'!$F$5:$K$10,6,FALSE),"Needs Improvement","Performance Improvement Required")))),"")) | AC8: =IF(COUNTA(G8:P8)+COUNTA(AD8:AE8)>0,"Entered","") | AF8: =IF(AD8<>"",AD8,AA8) | AG8: =IF(AE8<>"",AE8,AB8) | AH8: =D8&"|"&B8 -> Dennis Hartling|January
A9: 2026 | B9: January | C9: Joshio Flores | D9: Gilbert Eugene | F9: =IF(E9="","",IFERROR(VLOOKUP(E9,'Input & Settings'!$F$5:$G$10,2,FALSE),"")) | Q9: =IF(G9="","",IFERROR(MIN(100,G9/'Input & Settings'!$B$5*100),"")) | R9: =IF(H9="","",IFERROR(MIN(100,H9/'Input & Settings'!$B$6*100),"")) | S9: =IF(I9="","",IFERROR(MIN(100,I9/'Input & Settings'!$B$7*100),"")) | T9: =IF(J9="","",IFERROR(MIN(100,J9/'Input & Settings'!$B$8*100),"")) | U9: =IF(K9="","",IFERROR(MIN(100,K9/'Input & Settings'!$B$9*100),"")) | V9: =IF(L9="","",IFERROR(MIN(100,L9/'Input & Settings'!$B$10*100),"")) | W9: =IF(M9="","",IFERROR(IF(M9<='Input & Settings'!$B$11,100,MAX(0,100-(M9-'Input & Settings'!$B$11)*20)),"")) | X9: =IF(N9="","",IFERROR(MIN(100,N9/'Input & Settings'!$B$12*100),"")) | Y9: =IF(O9="","",IFERROR(MIN(100,O9/'Input & Settings'!$B$13*100),"")) | Z9: =IF(P9="","",IFERROR(IF(P9<='Input & Settings'!$B$14,100,MAX(0,100-(P9-'Input & Settings'!$B$14)*20)),"")) | AA9: =IF(COUNTA(G9:P9)=0,"",ROUND(Q9*'Input & Settings'!$C$5+R9*'Input & Settings'!$C$6+S9*'Input & Settings'!$C$7+T9*'Input & Settings'!$C$8+U9*'Input & Settings'!$C$9+V9*'Input & Settings'!$C$10+W9*'Input & Settings'!$C$11+X9*'Input & Settings'!$C$12+Y9*'Input & Settings'!$C$13+Z9*'Input & Settings'!$C$14,1)) | AB9: =IF(OR(AA9="",E9=""),"",IFERROR(IF(AA9>=VLOOKUP(E9,'Input & Settings'!$F$5:$K$10,3,FALSE),"Outstanding",IF(AA9>=VLOOKUP(E9,'Input & Settings'!$F$5:$K$10,4,FALSE),"Exceeds Expectations",IF(AA9>=VLOOKUP(E9,'Input & Settings'!$F$5:$K$10,5,FALSE),"Meets Expectations",IF(AA9>=VLOOKUP(E9,'Input & Settings'!$F$5:$K$10,6,FALSE),"Needs Improvement","Performance Improvement Required")))),"")) | AC9: =IF(COUNTA(G9:P9)+COUNTA(AD9:AE9)>0,"Entered","") | AF9: =IF(AD9<>"",AD9,AA9) | AG9: =IF(AE9<>"",AE9,AB9) | AH9: =D9&"|"&B9 -> Gilbert Eugene|January
A10: 2026 | B10: January | C10: Joshio Flores | D10: Cory Colstock | F10: =IF(E10="","",IFERROR(VLOOKUP(E10,'Input & Settings'!$F$5:$G$10,2,FALSE),"")) | Q10: =IF(G10="","",IFERROR(MIN(100,G10/'Input & Settings'!$B$5*100),"")) | R10: =IF(H10="","",IFERROR(MIN(100,H10/'Input & Settings'!$B$6*100),"")) | S10: =IF(I10="","",IFERROR(MIN(100,I10/'Input & Settings'!$B$7*100),"")) | T10: =IF(J10="","",IFERROR(MIN(100,J10/'Input & Settings'!$B$8*100),"")) | U10: =IF(K10="","",IFERROR(MIN(100,K10/'Input & Settings'!$B$9*100),"")) | V10: =IF(L10="","",IFERROR(MIN(100,L10/'Input & Settings'!$B$10*100),"")) | W10: =IF(M10="","",IFERROR(IF(M10<='Input & Settings'!$B$11,100,MAX(0,100-(M10-'Input & Settings'!$B$11)*20)),"")) | X10: =IF(N10="","",IFERROR(MIN(100,N10/'Input & Settings'!$B$12*100),"")) | Y10: =IF(O10="","",IFERROR(MIN(100,O10/'Input & Settings'!$B$13*100),"")) | Z10: =IF(P10="","",IFERROR(IF(P10<='Input & Settings'!$B$14,100,MAX(0,100-(P10-'Input & Settings'!$B$14)*20)),"")) | AA10: =IF(COUNTA(G10:P10)=0,"",ROUND(Q10*'Input & Settings'!$C$5+R10*'Input & Settings'!$C$6+S10*'Input & Settings'!$C$7+T10*'Input & Settings'!$C$8+U10*'Input & Settings'!$C$9+V10*'Input & Settings'!$C$10+W10*'Input & Settings'!$C$11+X10*'Input & Settings'!$C$12+Y10*'Input & Settings'!$C$13+Z10*'Input & Settings'!$C$14,1)) | AB10: =IF(OR(AA10="",E10=""),"",IFERROR(IF(AA10>=VLOOKUP(E10,'Input & Settings'!$F$5:$K$10,3,FALSE),"Outstanding",IF(AA10>=VLOOKUP(E10,'Input & Settings'!$F$5:$K$10,4,FALSE),"Exceeds Expectations",IF(AA10>=VLOOKUP(E10,'Input & Settings'!$F$5:$K$10,5,FALSE),"Meets Expectations",IF(AA10>=VLOOKUP(E10,'Input & Settings'!$F$5:$K$10,6,FALSE),"Needs Improvement","Performance Improvement Required")))),"")) | AC10: =IF(COUNTA(G10:P10)+COUNTA(AD10:AE10)>0,"Entered","") | AF10: =IF(AD10<>"",AD10,AA10) | AG10: =IF(AE10<>"",AE10,AB10) | AH10: =D10&"|"&B10 -> Cory Colstock|January
A11: 2026 | B11: January | C11: Joshio Flores | D11: Jerald Woodward (Jerry) | F11: =IF(E11="","",IFERROR(VLOOKUP(E11,'Input & Settings'!$F$5:$G$10,2,FALSE),"")) | Q11: =IF(G11="","",IFERROR(MIN(100,G11/'Input & Settings'!$B$5*100),"")) | R11: =IF(H11="","",IFERROR(MIN(100,H11/'Input & Settings'!$B$6*100),"")) | S11: =IF(I11="","",IFERROR(MIN(100,I11/'Input & Settings'!$B$7*100),"")) | T11: =IF(J11="","",IFERROR(MIN(100,J11/'Input & Settings'!$B$8*100),"")) | U11: =IF(K11="","",IFERROR(MIN(100,K11/'Input & Settings'!$B$9*100),"")) | V11: =IF(L11="","",IFERROR(MIN(100,L11/'Input & Settings'!$B$10*100),"")) | W11: =IF(M11="","",IFERROR(IF(M11<='Input & Settings'!$B$11,100,MAX(0,100-(M11-'Input & Settings'!$B$11)*20)),"")) | X11: =IF(N11="","",IFERROR(MIN(100,N11/'Input & Settings'!$B$12*100),"")) | Y11: =IF(O11="","",IFERROR(MIN(100,O11/'Input & Settings'!$B$13*100),"")) | Z11: =IF(P11="","",IFERROR(IF(P11<='Input & Settings'!$B$14,100,MAX(0,100-(P11-'Input & Settings'!$B$14)*20)),"")) | AA11: =IF(COUNTA(G11:P11)=0,"",ROUND(Q11*'Input & Settings'!$C$5+R11*'Input & Settings'!$C$6+S11*'Input & Settings'!$C$7+T11*'Input & Settings'!$C$8+U11*'Input & Settings'!$C$9+V11*'Input & Settings'!$C$10+W11*'Input & Settings'!$C$11+X11*'Input & Settings'!$C$12+Y11*'Input & Settings'!$C$13+Z11*'Input & Settings'!$C$14,1)) | AB11: =IF(OR(AA11="",E11=""),"",IFERROR(IF(AA11>=VLOOKUP(E11,'Input & Settings'!$F$5:$K$10,3,FALSE),"Outstanding",IF(AA11>=VLOOKUP(E11,'Input & Settings'!$F$5:$K$10,4,FALSE),"Exceeds Expectations",IF(AA11>=VLOOKUP(E11,'Input & Settings'!$F$5:$K$10,5,FALSE),"Meets Expectations",IF(AA11>=VLOOKUP(E11,'Input & Settings'!$F$5:$K$10,6,FALSE),"Needs Improvement","Performance Improvement Required")))),"")) | AC11: =IF(COUNTA(G11:P11)+COUNTA(AD11:AE11)>0,"Entered","") | AF11: =IF(AD11<>"",AD11,AA11) | AG11: =IF(AE11<>"",AE11,AB11) | AH11: =D11&"|"&B11 -> Jerald Woodward (Jerry)|January
A12: 2026 | B12: January | C12: Joshio Flores | D12: Alvaro Hernandez | F12: =IF(E12="","",IFERROR(VLOOKUP(E12,'Input & Settings'!$F$5:$G$10,2,FALSE),"")) | Q12: =IF(G12="","",IFERROR(MIN(100,G12/'Input & Settings'!$B$5*100),"")) | R12: =IF(H12="","",IFERROR(MIN(100,H12/'Input & Settings'!$B$6*100),"")) | S12: =IF(I12="","",IFERROR(MIN(100,I12/'Input & Settings'!$B$7*100),"")) | T12: =IF(J12="","",IFERROR(MIN(100,J12/'Input & Settings'!$B$8*100),"")) | U12: =IF(K12="","",IFERROR(MIN(100,K12/'Input & Settings'!$B$9*100),"")) | V12: =IF(L12="","",IFERROR(MIN(100,L12/'Input & Settings'!$B$10*100),"")) | W12: =IF(M12="","",IFERROR(IF(M12<='Input & Settings'!$B$11,100,MAX(0,100-(M12-'Input & Settings'!$B$11)*20)),"")) | X12: =IF(N12="","",IFERROR(MIN(100,N12/'Input & Settings'!$B$12*100),"")) | Y12: =IF(O12="","",IFERROR(MIN(100,O12/'Input & Settings'!$B$13*100),"")) | Z12: =IF(P12="","",IFERROR(IF(P12<='Input & Settings'!$B$14,100,MAX(0,100-(P12-'Input & Settings'!$B$14)*20)),"")) | AA12: =IF(COUNTA(G12:P12)=0,"",ROUND(Q12*'Input & Settings'!$C$5+R12*'Input & Settings'!$C$6+S12*'Input & Settings'!$C$7+T12*'Input & Settings'!$C$8+U12*'Input & Settings'!$C$9+V12*'Input & Settings'!$C$10+W12*'Input & Settings'!$C$11+X12*'Input & Settings'!$C$12+Y12*'Input & Settings'!$C$13+Z12*'Input & Settings'!$C$14,1)) | AB12: =IF(OR(AA12="",E12=""),"",IFERROR(IF(AA12>=VLOOKUP(E12,'Input & Settings'!$F$5:$K$10,3,FALSE),"Outstanding",IF(AA12>=VLOOKUP(E12,'Input & Settings'!$F$5:$K$10,4,FALSE),"Exceeds Expectations",IF(AA12>=VLOOKUP(E12,'Input & Settings'!$F$5:$K$10,5,FALSE),"Meets Expectations",IF(AA12>=VLOOKUP(E12,'Input & Settings'!$F$5:$K$10,6,FALSE),"Needs Improvement","Performance Improvement Required")))),"")) | AC12: =IF(COUNTA(G12:P12)+COUNTA(AD12:AE12)>0,"Entered","") | AF12: =IF(AD12<>"",AD12,AA12) | AG12: =IF(AE12<>"",AE12,AB12) | AH12: =D12&"|"&B12 -> Alvaro Hernandez|January
A13: 2026 | B13: January | C13: Joshio Flores | D13: Sarah Clervil | F13: =IF(E13="","",IFERROR(VLOOKUP(E13,'Input & Settings'!$F$5:$G$10,2,FALSE),"")) | Q13: =IF(G13="","",IFERROR(MIN(100,G13/'Input & Settings'!$B$5*100),"")) | R13: =IF(H13="","",IFERROR(MIN(100,H13/'Input & Settings'!$B$6*100),"")) | S13: =IF(I13="","",IFERROR(MIN(100,I13/'Input & Settings'!$B$7*100),"")) | T13: =IF(J13="","",IFERROR(MIN(100,J13/'Input & Settings'!$B$8*100),"")) | U13: =IF(K13="","",IFERROR(MIN(100,K13/'Input & Settings'!$B$9*100),"")) | V13: =IF(L13="","",IFERROR(MIN(100,L13/'Input & Settings'!$B$10*100),"")) | W13: =IF(M13="","",IFERROR(IF(M13<='Input & Settings'!$B$11,100,MAX(0,100-(M13-'Input & Settings'!$B$11)*20)),"")) | X13: =IF(N13="","",IFERROR(MIN(100,N13/'Input & Settings'!$B$12*100),"")) | Y13: =IF(O13="","",IFERROR(MIN(100,O13/'Input & Settings'!$B$13*100),"")) | Z13: =IF(P13="","",IFERROR(IF(P13<='Input & Settings'!$B$14,100,MAX(0,100-(P13-'Input & Settings'!$B$14)*20)),"")) | AA13: =IF(COUNTA(G13:P13)=0,"",ROUND(Q13*'Input & Settings'!$C$5+R13*'Input & Settings'!$C$6+S13*'Input & Settings'!$C$7+T13*'Input & Settings'!$C$8+U13*'Input & Settings'!$C$9+V13*'Input & Settings'!$C$10+W13*'Input & Settings'!$C$11+X13*'Input & Settings'!$C$12+Y13*'Input & Settings'!$C$13+Z13*'Input & Settings'!$C$14,1)) | AB13: =IF(OR(AA13="",E13=""),"",IFERROR(IF(AA13>=VLOOKUP(E13,'Input & Settings'!$F$5:$K$10,3,FALSE),"Outstanding",IF(AA13>=VLOOKUP(E13,'Input & Settings'!$F$5:$K$10,4,FALSE),"Exceeds Expectations",IF(AA13>=VLOOKUP(E13,'Input & Settings'!$F$5:$K$10,5,FALSE),"Meets Expectations",IF(AA13>=VLOOKUP(E13,'Input & Settings'!$F$5:$K$10,6,FALSE),"Needs Improvement","Performance Improvement Required")))),"")) | AC13: =IF(COUNTA(G13:P13)+COUNTA(AD13:AE13)>0,"Entered","") | AF13: =IF(AD13<>"",AD13,AA13) | AG13: =IF(AE13<>"",AE13,AB13) | AH13: =D13&"|"&B13 -> Sarah Clervil|January
A14: 2026 | B14: January | C14: Joshio Flores | D14: Christopher Ovid | F14: =IF(E14="","",IFERROR(VLOOKUP(E14,'Input & Settings'!$F$5:$G$10,2,FALSE),"")) | Q14: =IF(G14="","",IFERROR(MIN(100,G14/'Input & Settings'!$B$5*100),"")) | R14: =IF(H14="","",IFERROR(MIN(100,H14/'Input & Settings'!$B$6*100),"")) | S14: =IF(I14="","",IFERROR(MIN(100,I14/'Input & Settings'!$B$7*100),"")) | T14: =IF(J14="","",IFERROR(MIN(100,J14/'Input & Settings'!$B$8*100),"")) | U14: =IF(K14="","",IFERROR(MIN(100,K14/'Input & Settings'!$B$9*100),"")) | V14: =IF(L14="","",IFERROR(MIN(100,L14/'Input & Settings'!$B$10*100),"")) | W14: =IF(M14="","",IFERROR(IF(M14<='Input & Settings'!$B$11,100,MAX(0,100-(M14-'Input & Settings'!$B$11)*20)),"")) | X14: =IF(N14="","",IFERROR(MIN(100,N14/'Input & Settings'!$B$12*100),"")) | Y14: =IF(O14="","",IFERROR(MIN(100,O14/'Input & Settings'!$B$13*100),"")) | Z14: =IF(P14="","",IFERROR(IF(P14<='Input & Settings'!$B$14,100,MAX(0,100-(P14-'Input & Settings'!$B$14)*20)),"")) | AA14: =IF(COUNTA(G14:P14)=0,"",ROUND(Q14*'Input & Settings'!$C$5+R14*'Input & Settings'!$C$6+S14*'Input & Settings'!$C$7+T14*'Input & Settings'!$C$8+U14*'Input & Settings'!$C$9+V14*'Input & Settings'!$C$10+W14*'Input & Settings'!$C$11+X14*'Input & Settings'!$C$12+Y14*'Input & Settings'!$C$13+Z14*'Input & Settings'!$C$14,1)) | AB14: =IF(OR(AA14="",E14=""),"",IFERROR(IF(AA14>=VLOOKUP(E14,'Input & Settings'!$F$5:$K$10,3,FALSE),"Outstanding",IF(AA14>=VLOOKUP(E14,'Input & Settings'!$F$5:$K$10,4,FALSE),"Exceeds Expectations",IF(AA14>=VLOOKUP(E14,'Input & Settings'!$F$5:$K$10,5,FALSE),"Meets Expectations",IF(AA14>=VLOOKUP(E14,'Input & Settings'!$F$5:$K$10,6,FALSE),"Needs Improvement","Performance Improvement Required")))),"")) | AC14: =IF(COUNTA(G14:P14)+COUNTA(AD14:AE14)>0,"Entered","") | AF14: =IF(AD14<>"",AD14,AA14) | AG14: =IF(AE14<>"",AE14,AB14) | AH14: =D14&"|"&B14 -> Christopher Ovid|January
... A212: 2026 | B212: May | C212: Jose Molina | D212: Angel Perez Martinez | F212: =IF(E212="","",IFERROR(VLOOKUP(E212,'Input & Settings'!$F$5:$G$10,2,FALSE),"")) | Q212: =IF(G212="","",IFERROR(MIN(100,G212/'Input & Settings'!$B$5*100),"")) | R212: =IF(H212="","",IFERROR(MIN(100,H212/'Input & Settings'!$B$6*100),"")) | S212: =IF(I212="","",IFERROR(MIN(100,I212/'Input & Settings'!$B$7*100),"")) | T212: =IF(J212="","",IFERROR(MIN(100,J212/'Input & Settings'!$B$8*100),"")) | U212: =IF(K212="","",IFERROR(MIN(100,K212/'Input & Settings'!$B$9*100),"")) | V212: =IF(L212="","",IFERROR(MIN(100,L212/'Input & Settings'!$B$10*100),"")) | W212: =IF(M212="","",IFERROR(IF(M212<='Input & Settings'!$B$11,100,MAX(0,100-(M212-'Input & Settings'!$B$11)*20)),"")) | X212: =IF(N212="","",IFERROR(MIN(100,N212/'Input & Settings'!$B$12*100),"")) | Y212: =IF(O212="","",IFERROR(MIN(100,O212/'Input & Settings'!$B$13*100),"")) | Z212: =IF(P212="","",IFERROR(IF(P212<='Input & Settings'!$B$14,100,MAX(0,100-(P212-'Input & Settings'!$B$14)*20)),"")) | AA212: =IF(COUNTA(G212:P212)=0,"",ROUND(Q212*'Input & Settings'!$C$5+R212*'Input & Settings'!$C$6+S212*'Input & Settings'!$C$7+T212*'Input & Settings'!$C$8+U212*'Input & Settings'!$C$9+V212*'Input & Settings'!$C$10+W212*'Input & Settings'!$C$11+X212*'Input & Settings'!$C$12+Y212*'Input & Settings'!$C$13+Z212*'Input & Settings'!$C$14,1)) | AB212: =IF(OR(AA212="",E212=""),"",IFERROR(IF(AA212>=VLOOKUP(E212,'Input & Settings'!$F$5:$K$10,3,FALSE),"Outstanding",IF(AA212>=VLOOKUP(E212,'Input & Settings'!$F$5:$K$10,4,FALSE),"Exceeds Expectations",IF(AA212>=VLOOKUP(E212,'Input & Settings'!$F$5:$K$10,5,FALSE),"Meets Expectations",IF(AA212>=VLOOKUP(E212,'Input & Settings'!$F$5:$K$10,6,FALSE),"Needs Improvement","Performance Improvement Required")))),"")) | AC212: =IF(COUNTA(G212:P212)+COUNTA(AD212:AE212)>0,"Entered","") | AF212: =IF(AD212<>"",AD212,AA212) | AG212: =IF(AE212<>"",AE212,AB212) | AH212: =D212&"|"&B212 -> Angel Perez Martinez|May
A213: 2026 | B213: June | C213: Joshio Flores | D213: Carly Huber | E213: 1st Shift | F213: =IF(E213="","",IFERROR(VLOOKUP(E213,'Input & Settings'!$F$5:$G$10,2,FALSE),"")) -> High | Q213: =IF(G213="","",IFERROR(MIN(100,G213/'Input & Settings'!$B$5*100),"")) | R213: =IF(H213="","",IFERROR(MIN(100,H213/'Input & Settings'!$B$6*100),"")) | S213: =IF(I213="","",IFERROR(MIN(100,I213/'Input & Settings'!$B$7*100),"")) | T213: =IF(J213="","",IFERROR(MIN(100,J213/'Input & Settings'!$B$8*100),"")) | U213: =IF(K213="","",IFERROR(MIN(100,K213/'Input & Settings'!$B$9*100),"")) | V213: =IF(L213="","",IFERROR(MIN(100,L213/'Input & Settings'!$B$10*100),"")) | W213: =IF(M213="","",IFERROR(IF(M213<='Input & Settings'!$B$11,100,MAX(0,100-(M213-'Input & Settings'!$B$11)*20)),"")) | X213: =IF(N213="","",IFERROR(MIN(100,N213/'Input & Settings'!$B$12*100),"")) | Y213: =IF(O213="","",IFERROR(MIN(100,O213/'Input & Settings'!$B$13*100),"")) | Z213: =IF(P213="","",IFERROR(IF(P213<='Input & Settings'!$B$14,100,MAX(0,100-(P213-'Input & Settings'!$B$14)*20)),"")) | AA213: =IF(COUNTA(G213:P213)=0,"",ROUND(Q213*'Input & Settings'!$C$5+R213*'Input & Settings'!$C$6+S213*'Input & Settings'!$C$7+T213*'Input & Settings'!$C$8+U213*'Input & Settings'!$C$9+V213*'Input & Settings'!$C$10+W213*'Input & Settings'!$C$11+X213*'Input & Settings'!$C$12+Y213*'Input & Settings'!$C$13+Z213*'Input & Settings'!$C$14,1)) | AB213: =IF(OR(AA213="",E213=""),"",IFERROR(IF(AA213>=VLOOKUP(E213,'Input & Settings'!$F$5:$K$10,3,FALSE),"Outstanding",IF(AA213>=VLOOKUP(E213,'Input & Settings'!$F$5:$K$10,4,FALSE),"Exceeds Expectations",IF(AA213>=VLOOKUP(E213,'Input & Settings'!$F$5:$K$10,5,FALSE),"Meets Expectations",IF(AA213>=VLOOKUP(E213,'Input & Settings'!$F$5:$K$10,6,FALSE),"Needs Improvement","Performance Improvement Required")))),"")) | AC213: =IF(COUNTA(G213:P213)+COUNTA(AD213:AE213)>0,"Entered","") | AF213: =IF(AD213<>"",AD213,AA213) | AG213: =IF(AE213<>"",AE213,AB213) | AH213: =D213&"|"&B213 -> Carly Huber|June
A214: 2026 | B214: June | C214: Joshio Flores | D214: Julian Grier | F214: =IF(E214="","",IFERROR(VLOOKUP(E214,'Input & Settings'!$F$5:$G$10,2,FALSE),"")) | Q214: =IF(G214="","",IFERROR(MIN(100,G214/'Input & Settings'!$B$5*100),"")) | R214: =IF(H214="","",IFERROR(MIN(100,H214/'Input & Settings'!$B$6*100),"")) | S214: =IF(I214="","",IFERROR(MIN(100,I214/'Input & Settings'!$B$7*100),"")) | T214: =IF(J214="","",IFERROR(MIN(100,J214/'Input & Settings'!$B$8*100),"")) | U214: =IF(K214="","",IFERROR(MIN(100,K214/'Input & Settings'!$B$9*100),"")) | V214: =IF(L214="","",IFERROR(MIN(100,L214/'Input & Settings'!$B$10*100),"")) | W214: =IF(M214="","",IFERROR(IF(M214<='Input & Settings'!$B$11,100,MAX(0,100-(M214-'Input & Settings'!$B$11)*20)),"")) | X214: =IF(N214="","",IFERROR(MIN(100,N214/'Input & Settings'!$B$12*100),"")) | Y214: =IF(O214="","",IFERROR(MIN(100,O214/'Input & Settings'!$B$13*100),"")) | Z214: =IF(P214="","",IFERROR(IF(P214<='Input & Settings'!$B$14,100,MAX(0,100-(P214-'Input & Settings'!$B$14)*20)),"")) | AA214: =IF(COUNTA(G214:P214)=0,"",ROUND(Q214*'Input & Settings'!$C$5+R214*'Input & Settings'!$C$6+S214*'Input & Settings'!$C$7+T214*'Input & Settings'!$C$8+U214*'Input & Settings'!$C$9+V214*'Input & Settings'!$C$10+W214*'Input & Settings'!$C$11+X214*'Input & Settings'!$C$12+Y214*'Input & Settings'!$C$13+Z214*'Input & Settings'!$C$14,1)) | AB214: =IF(OR(AA214="",E214=""),"",IFERROR(IF(AA214>=VLOOKUP(E214,'Input & Settings'!$F$5:$K$10,3,FALSE),"Outstanding",IF(AA214>=VLOOKUP(E214,'Input & Settings'!$F$5:$K$10,4,FALSE),"Exceeds Expectations",IF(AA214>=VLOOKUP(E214,'Input & Settings'!$F$5:$K$10,5,FALSE),"Meets Expectations",IF(AA214>=VLOOKUP(E214,'Input & Settings'!$F$5:$K$10,6,FALSE),"Needs Improvement","Performance Improvement Required")))),"")) | AC214: =IF(COUNTA(G214:P214)+COUNTA(AD214:AE214)>0,"Entered","") | AF214: =IF(AD214<>"",AD214,AA214) | AG214: =IF(AE214<>"",AE214,AB214) | AH214: =D214&"|"&B214 -> Julian Grier|June
A215: 2026 | B215: June | C215: Joshio Flores | D215: Jorge Lopez | F215: =IF(E215="","",IFERROR(VLOOKUP(E215,'Input & Settings'!$F$5:$G$10,2,FALSE),"")) | Q215: =IF(G215="","",IFERROR(MIN(100,G215/'Input & Settings'!$B$5*100),"")) | R215: =IF(H215="","",IFERROR(MIN(100,H215/'Input & Settings'!$B$6*100),"")) | S215: =IF(I215="","",IFERROR(MIN(100,I215/'Input & Settings'!$B$7*100),"")) | T215: =IF(J215="","",IFERROR(MIN(100,J215/'Input & Settings'!$B$8*100),"")) | U215: =IF(K215="","",IFERROR(MIN(100,K215/'Input & Settings'!$B$9*100),"")) | V215: =IF(L215="","",IFERROR(MIN(100,L215/'Input & Settings'!$B$10*100),"")) | W215: =IF(M215="","",IFERROR(IF(M215<='Input & Settings'!$B$11,100,MAX(0,100-(M215-'Input & Settings'!$B$11)*20)),"")) | X215: =IF(N215="","",IFERROR(MIN(100,N215/'Input & Settings'!$B$12*100),"")) | Y215: =IF(O215="","",IFERROR(MIN(100,O215/'Input & Settings'!$B$13*100),"")) | Z215: =IF(P215="","",IFERROR(IF(P215<='Input & Settings'!$B$14,100,MAX(0,100-(P215-'Input & Settings'!$B$14)*20)),"")) | AA215: =IF(COUNTA(G215:P215)=0,"",ROUND(Q215*'Input & Settings'!$C$5+R215*'Input & Settings'!$C$6+S215*'Input & Settings'!$C$7+T215*'Input & Settings'!$C$8+U215*'Input & Settings'!$C$9+V215*'Input & Settings'!$C$10+W215*'Input & Settings'!$C$11+X215*'Input & Settings'!$C$12+Y215*'Input & Settings'!$C$13+Z215*'Input & Settings'!$C$14,1)) | AB215: =IF(OR(AA215="",E215=""),"",IFERROR(IF(AA215>=VLOOKUP(E215,'Input & Settings'!$F$5:$K$10,3,FALSE),"Outstanding",IF(AA215>=VLOOKUP(E215,'Input & Settings'!$F$5:$K$10,4,FALSE),"Exceeds Expectations",IF(AA215>=VLOOKUP(E215,'Input & Settings'!$F$5:$K$10,5,FALSE),"Meets Expectations",IF(AA215>=VLOOKUP(E215,'Input & Settings'!$F$5:$K$10,6,FALSE),"Needs Improvement","Performance Improvement Required")))),"")) | AC215: =IF(COUNTA(G215:P215)+COUNTA(AD215:AE215)>0,"Entered","") | AF215: =IF(AD215<>"",AD215,AA215) | AG215: =IF(AE215<>"",AE215,AB215) | AH215: =D215&"|"&B215 -> Jorge Lopez|June
A216: 2026 | B216: June | C216: Joshio Flores | D216: Juan Pablo Pique Buil (JP) | F216: =IF(E216="","",IFERROR(VLOOKUP(E216,'Input & Settings'!$F$5:$G$10,2,FALSE),"")) | Q216: =IF(G216="","",IFERROR(MIN(100,G216/'Input & Settings'!$B$5*100),"")) | R216: =IF(H216="","",IFERROR(MIN(100,H216/'Input & Settings'!$B$6*100),"")) | S216: =IF(I216="","",IFERROR(MIN(100,I216/'Input & Settings'!$B$7*100),"")) | T216: =IF(J216="","",IFERROR(MIN(100,J216/'Input & Settings'!$B$8*100),"")) | U216: =IF(K216="","",IFERROR(MIN(100,K216/'Input & Settings'!$B$9*100),"")) | V216: =IF(L216="","",IFERROR(MIN(100,L216/'Input & Settings'!$B$10*100),"")) | W216: =IF(M216="","",IFERROR(IF(M216<='Input & Settings'!$B$11,100,MAX(0,100-(M216-'Input & Settings'!$B$11)*20)),"")) | X216: =IF(N216="","",IFERROR(MIN(100,N216/'Input & Settings'!$B$12*100),"")) | Y216: =IF(O216="","",IFERROR(MIN(100,O216/'Input & Settings'!$B$13*100),"")) | Z216: =IF(P216="","",IFERROR(IF(P216<='Input & Settings'!$B$14,100,MAX(0,100-(P216-'Input & Settings'!$B$14)*20)),"")) | AA216: =IF(COUNTA(G216:P216)=0,"",ROUND(Q216*'Input & Settings'!$C$5+R216*'Input & Settings'!$C$6+S216*'Input & Settings'!$C$7+T216*'Input & Settings'!$C$8+U216*'Input & Settings'!$C$9+V216*'Input & Settings'!$C$10+W216*'Input & Settings'!$C$11+X216*'Input & Settings'!$C$12+Y216*'Input & Settings'!$C$13+Z216*'Input & Settings'!$C$14,1)) | AB216: =IF(OR(AA216="",E216=""),"",IFERROR(IF(AA216>=VLOOKUP(E216,'Input & Settings'!$F$5:$K$10,3,FALSE),"Outstanding",IF(AA216>=VLOOKUP(E216,'Input & Settings'!$F$5:$K$10,4,FALSE),"Exceeds Expectations",IF(AA216>=VLOOKUP(E216,'Input & Settings'!$F$5:$K$10,5,FALSE),"Meets Expectations",IF(AA216>=VLOOKUP(E216,'Input & Settings'!$F$5:$K$10,6,FALSE),"Needs Improvement","Performance Improvement Required")))),"")) | AC216: =IF(COUNTA(G216:P216)+COUNTA(AD216:AE216)>0,"Entered","") | AF216: =IF(AD216<>"",AD216,AA216) | AG216: =IF(AE216<>"",AE216,AB216) | AH216: =D216&"|"&B216 -> Juan Pablo Pique Buil (JP)|June
A217: 2026 | B217: June | C217: Joshio Flores | D217: Peter Gonzalez | F217: =IF(E217="","",IFERROR(VLOOKUP(E217,'Input & Settings'!$F$5:$G$10,2,FALSE),"")) | Q217: =IF(G217="","",IFERROR(MIN(100,G217/'Input & Settings'!$B$5*100),"")) | R217: =IF(H217="","",IFERROR(MIN(100,H217/'Input & Settings'!$B$6*100),"")) | S217: =IF(I217="","",IFERROR(MIN(100,I217/'Input & Settings'!$B$7*100),"")) | T217: =IF(J217="","",IFERROR(MIN(100,J217/'Input & Settings'!$B$8*100),"")) | U217: =IF(K217="","",IFERROR(MIN(100,K217/'Input & Settings'!$B$9*100),"")) | V217: =IF(L217="","",IFERROR(MIN(100,L217/'Input & Settings'!$B$10*100),"")) | W217: =IF(M217="","",IFERROR(IF(M217<='Input & Settings'!$B$11,100,MAX(0,100-(M217-'Input & Settings'!$B$11)*20)),"")) | X217: =IF(N217="","",IFERROR(MIN(100,N217/'Input & Settings'!$B$12*100),"")) | Y217: =IF(O217="","",IFERROR(MIN(100,O217/'Input & Settings'!$B$13*100),"")) | Z217: =IF(P217="","",IFERROR(IF(P217<='Input & Settings'!$B$14,100,MAX(0,100-(P217-'Input & Settings'!$B$14)*20)),"")) | AA217: =IF(COUNTA(G217:P217)=0,"",ROUND(Q217*'Input & Settings'!$C$5+R217*'Input & Settings'!$C$6+S217*'Input & Settings'!$C$7+T217*'Input & Settings'!$C$8+U217*'Input & Settings'!$C$9+V217*'Input & Settings'!$C$10+W217*'Input & Settings'!$C$11+X217*'Input & Settings'!$C$12+Y217*'Input & Settings'!$C$13+Z217*'Input & Settings'!$C$14,1)) | AB217: =IF(OR(AA217="",E217=""),"",IFERROR(IF(AA217>=VLOOKUP(E217,'Input & Settings'!$F$5:$K$10,3,FALSE),"Outstanding",IF(AA217>=VLOOKUP(E217,'Input & Settings'!$F$5:$K$10,4,FALSE),"Exceeds Expectations",IF(AA217>=VLOOKUP(E217,'Input & Settings'!$F$5:$K$10,5,FALSE),"Meets Expectations",IF(AA217>=VLOOKUP(E217,'Input & Settings'!$F$5:$K$10,6,FALSE),"Needs Improvement","Performance Improvement Required")))),"")) | AC217: =IF(COUNTA(G217:P217)+COUNTA(AD217:AE217)>0,"Entered","") | AF217: =IF(AD217<>"",AD217,AA217) | AG217: =IF(AE217<>"",AE217,AB217) | AH217: =D217&"|"&B217 -> Peter Gonzalez|June
A218: 2026 | B218: June | C218: Joshio Flores | D218: Dennis Hartling | F218: =IF(E218="","",IFERROR(VLOOKUP(E218,'Input & Settings'!$F$5:$G$10,2,FALSE),"")) | Q218: =IF(G218="","",IFERROR(MIN(100,G218/'Input & Settings'!$B$5*100),"")) | R218: =IF(H218="","",IFERROR(MIN(100,H218/'Input & Settings'!$B$6*100),"")) | S218: =IF(I218="","",IFERROR(MIN(100,I218/'Input & Settings'!$B$7*100),"")) | T218: =IF(J218="","",IFERROR(MIN(100,J218/'Input & Settings'!$B$8*100),"")) | U218: =IF(K218="","",IFERROR(MIN(100,K218/'Input & Settings'!$B$9*100),"")) | V218: =IF(L218="","",IFERROR(MIN(100,L218/'Input & Settings'!$B$10*100),"")) | W218: =IF(M218="","",IFERROR(IF(M218<='Input & Settings'!$B$11,100,MAX(0,100-(M218-'Input & Settings'!$B$11)*20)),"")) | X218: =IF(N218="","",IFERROR(MIN(100,N218/'Input & Settings'!$B$12*100),"")) | Y218: =IF(O218="","",IFERROR(MIN(100,O218/'Input & Settings'!$B$13*100),"")) | Z218: =IF(P218="","",IFERROR(IF(P218<='Input & Settings'!$B$14,100,MAX(0,100-(P218-'Input & Settings'!$B$14)*20)),"")) | AA218: =IF(COUNTA(G218:P218)=0,"",ROUND(Q218*'Input & Settings'!$C$5+R218*'Input & Settings'!$C$6+S218*'Input & Settings'!$C$7+T218*'Input & Settings'!$C$8+U218*'Input & Settings'!$C$9+V218*'Input & Settings'!$C$10+W218*'Input & Settings'!$C$11+X218*'Input & Settings'!$C$12+Y218*'Input & Settings'!$C$13+Z218*'Input & Settings'!$C$14,1)) | AB218: =IF(OR(AA218="",E218=""),"",IFERROR(IF(AA218>=VLOOKUP(E218,'Input & Settings'!$F$5:$K$10,3,FALSE),"Outstanding",IF(AA218>=VLOOKUP(E218,'Input & Settings'!$F$5:$K$10,4,FALSE),"Exceeds Expectations",IF(AA218>=VLOOKUP(E218,'Input & Settings'!$F$5:$K$10,5,FALSE),"Meets Expectations",IF(AA218>=VLOOKUP(E218,'Input & Settings'!$F$5:$K$10,6,FALSE),"Needs Improvement","Performance Improvement Required")))),"")) | AC218: =IF(COUNTA(G218:P218)+COUNTA(AD218:AE218)>0,"Entered","") | AF218: =IF(AD218<>"",AD218,AA218) | AG218: =IF(AE218<>"",AE218,AB218) | AH218: =D218&"|"&B218 -> Dennis Hartling|June
A219: 2026 | B219: June | C219: Joshio Flores | D219: Gilbert Eugene | F219: =IF(E219="","",IFERROR(VLOOKUP(E219,'Input & Settings'!$F$5:$G$10,2,FALSE),"")) | Q219: =IF(G219="","",IFERROR(MIN(100,G219/'Input & Settings'!$B$5*100),"")) | R219: =IF(H219="","",IFERROR(MIN(100,H219/'Input & Settings'!$B$6*100),"")) | S219: =IF(I219="","",IFERROR(MIN(100,I219/'Input & Settings'!$B$7*100),"")) | T219: =IF(J219="","",IFERROR(MIN(100,J219/'Input & Settings'!$B$8*100),"")) | U219: =IF(K219="","",IFERROR(MIN(100,K219/'Input & Settings'!$B$9*100),"")) | V219: =IF(L219="","",IFERROR(MIN(100,L219/'Input & Settings'!$B$10*100),"")) | W219: =IF(M219="","",IFERROR(IF(M219<='Input & Settings'!$B$11,100,MAX(0,100-(M219-'Input & Settings'!$B$11)*20)),"")) | X219: =IF(N219="","",IFERROR(MIN(100,N219/'Input & Settings'!$B$12*100),"")) | Y219: =IF(O219="","",IFERROR(MIN(100,O219/'Input & Settings'!$B$13*100),"")) | Z219: =IF(P219="","",IFERROR(IF(P219<='Input & Settings'!$B$14,100,MAX(0,100-(P219-'Input & Settings'!$B$14)*20)),"")) | AA219: =IF(COUNTA(G219:P219)=0,"",ROUND(Q219*'Input & Settings'!$C$5+R219*'Input & Settings'!$C$6+S219*'Input & Settings'!$C$7+T219*'Input & Settings'!$C$8+U219*'Input & Settings'!$C$9+V219*'Input & Settings'!$C$10+W219*'Input & Settings'!$C$11+X219*'Input & Settings'!$C$12+Y219*'Input & Settings'!$C$13+Z219*'Input & Settings'!$C$14,1)) | AB219: =IF(OR(AA219="",E219=""),"",IFERROR(IF(AA219>=VLOOKUP(E219,'Input & Settings'!$F$5:$K$10,3,FALSE),"Outstanding",IF(AA219>=VLOOKUP(E219,'Input & Settings'!$F$5:$K$10,4,FALSE),"Exceeds Expectations",IF(AA219>=VLOOKUP(E219,'Input & Settings'!$F$5:$K$10,5,FALSE),"Meets Expectations",IF(AA219>=VLOOKUP(E219,'Input & Settings'!$F$5:$K$10,6,FALSE),"Needs Improvement","Performance Improvement Required")))),"")) | AC219: =IF(COUNTA(G219:P219)+COUNTA(AD219:AE219)>0,"Entered","") | AF219: =IF(AD219<>"",AD219,AA219) | AG219: =IF(AE219<>"",AE219,AB219) | AH219: =D219&"|"&B219 -> Gilbert Eugene|June
A220: 2026 | B220: June | C220: Joshio Flores | D220: Cory Colstock | F220: =IF(E220="","",IFERROR(VLOOKUP(E220,'Input & Settings'!$F$5:$G$10,2,FALSE),"")) | Q220: =IF(G220="","",IFERROR(MIN(100,G220/'Input & Settings'!$B$5*100),"")) | R220: =IF(H220="","",IFERROR(MIN(100,H220/'Input & Settings'!$B$6*100),"")) | S220: =IF(I220="","",IFERROR(MIN(100,I220/'Input & Settings'!$B$7*100),"")) | T220: =IF(J220="","",IFERROR(MIN(100,J220/'Input & Settings'!$B$8*100),"")) | U220: =IF(K220="","",IFERROR(MIN(100,K220/'Input & Settings'!$B$9*100),"")) | V220: =IF(L220="","",IFERROR(MIN(100,L220/'Input & Settings'!$B$10*100),"")) | W220: =IF(M220="","",IFERROR(IF(M220<='Input & Settings'!$B$11,100,MAX(0,100-(M220-'Input & Settings'!$B$11)*20)),"")) | X220: =IF(N220="","",IFERROR(MIN(100,N220/'Input & Settings'!$B$12*100),"")) | Y220: =IF(O220="","",IFERROR(MIN(100,O220/'Input & Settings'!$B$13*100),"")) | Z220: =IF(P220="","",IFERROR(IF(P220<='Input & Settings'!$B$14,100,MAX(0,100-(P220-'Input & Settings'!$B$14)*20)),"")) | AA220: =IF(COUNTA(G220:P220)=0,"",ROUND(Q220*'Input & Settings'!$C$5+R220*'Input & Settings'!$C$6+S220*'Input & Settings'!$C$7+T220*'Input & Settings'!$C$8+U220*'Input & Settings'!$C$9+V220*'Input & Settings'!$C$10+W220*'Input & Settings'!$C$11+X220*'Input & Settings'!$C$12+Y220*'Input & Settings'!$C$13+Z220*'Input & Settings'!$C$14,1)) | AB220: =IF(OR(AA220="",E220=""),"",IFERROR(IF(AA220>=VLOOKUP(E220,'Input & Settings'!$F$5:$K$10,3,FALSE),"Outstanding",IF(AA220>=VLOOKUP(E220,'Input & Settings'!$F$5:$K$10,4,FALSE),"Exceeds Expectations",IF(AA220>=VLOOKUP(E220,'Input & Settings'!$F$5:$K$10,5,FALSE),"Meets Expectations",IF(AA220>=VLOOKUP(E220,'Input & Settings'!$F$5:$K$10,6,FALSE),"Needs Improvement","Performance Improvement Required")))),"")) | AC220: =IF(COUNTA(G220:P220)+COUNTA(AD220:AE220)>0,"Entered","") | AF220: =IF(AD220<>"",AD220,AA220) | AG220: =IF(AE220<>"",AE220,AB220) | AH220: =D220&"|"&B220 -> Cory Colstock|June
A221: 2026 | B221: June | C221: Joshio Flores | D221: Jerald Woodward (Jerry) | F221: =IF(E221="","",IFERROR(VLOOKUP(E221,'Input & Settings'!$F$5:$G$10,2,FALSE),"")) | Q221: =IF(G221="","",IFERROR(MIN(100,G221/'Input & Settings'!$B$5*100),"")) | R221: =IF(H221="","",IFERROR(MIN(100,H221/'Input & Settings'!$B$6*100),"")) | S221: =IF(I221="","",IFERROR(MIN(100,I221/'Input & Settings'!$B$7*100),"")) | T221: =IF(J221="","",IFERROR(MIN(100,J221/'Input & Settings'!$B$8*100),"")) | U221: =IF(K221="","",IFERROR(MIN(100,K221/'Input & Settings'!$B$9*100),"")) | V221: =IF(L221="","",IFERROR(MIN(100,L221/'Input & Settings'!$B$10*100),"")) | W221: =IF(M221="","",IFERROR(IF(M221<='Input & Settings'!$B$11,100,MAX(0,100-(M221-'Input & Settings'!$B$11)*20)),"")) | X221: =IF(N221="","",IFERROR(MIN(100,N221/'Input & Settings'!$B$12*100),"")) | Y221: =IF(O221="","",IFERROR(MIN(100,O221/'Input & Settings'!$B$13*100),"")) | Z221: =IF(P221="","",IFERROR(IF(P221<='Input & Settings'!$B$14,100,MAX(0,100-(P221-'Input & Settings'!$B$14)*20)),"")) | AA221: =IF(COUNTA(G221:P221)=0,"",ROUND(Q221*'Input & Settings'!$C$5+R221*'Input & Settings'!$C$6+S221*'Input & Settings'!$C$7+T221*'Input & Settings'!$C$8+U221*'Input & Settings'!$C$9+V221*'Input & Settings'!$C$10+W221*'Input & Settings'!$C$11+X221*'Input & Settings'!$C$12+Y221*'Input & Settings'!$C$13+Z221*'Input & Settings'!$C$14,1)) | AB221: =IF(OR(AA221="",E221=""),"",IFERROR(IF(AA221>=VLOOKUP(E221,'Input & Settings'!$F$5:$K$10,3,FALSE),"Outstanding",IF(AA221>=VLOOKUP(E221,'Input & Settings'!$F$5:$K$10,4,FALSE),"Exceeds Expectations",IF(AA221>=VLOOKUP(E221,'Input & Settings'!$F$5:$K$10,5,FALSE),"Meets Expectations",IF(AA221>=VLOOKUP(E221,'Input & Settings'!$F$5:$K$10,6,FALSE),"Needs Improvement","Performance Improvement Required")))),"")) | AC221: =IF(COUNTA(G221:P221)+COUNTA(AD221:AE221)>0,"Entered","") | AF221: =IF(AD221<>"",AD221,AA221) | AG221: =IF(AE221<>"",AE221,AB221) | AH221: =D221&"|"&B221 -> Jerald Woodward (Jerry)|June
A222: 2026 | B222: June | C222: Joshio Flores | D222: Alvaro Hernandez | E222: 1st Shift | F222: =IF(E222="","",IFERROR(VLOOKUP(E222,'Input & Settings'!$F$5:$G$10,2,FALSE),"")) -> High | Q222: =IF(G222="","",IFERROR(MIN(100,G222/'Input & Settings'!$B$5*100),"")) | R222: =IF(H222="","",IFERROR(MIN(100,H222/'Input & Settings'!$B$6*100),"")) | S222: =IF(I222="","",IFERROR(MIN(100,I222/'Input & Settings'!$B$7*100),"")) | T222: =IF(J222="","",IFERROR(MIN(100,J222/'Input & Settings'!$B$8*100),"")) | U222: =IF(K222="","",IFERROR(MIN(100,K222/'Input & Settings'!$B$9*100),"")) | V222: =IF(L222="","",IFERROR(MIN(100,L222/'Input & Settings'!$B$10*100),"")) | W222: =IF(M222="","",IFERROR(IF(M222<='Input & Settings'!$B$11,100,MAX(0,100-(M222-'Input & Settings'!$B$11)*20)),"")) | X222: =IF(N222="","",IFERROR(MIN(100,N222/'Input & Settings'!$B$12*100),"")) | Y222: =IF(O222="","",IFERROR(MIN(100,O222/'Input & Settings'!$B$13*100),"")) | Z222: =IF(P222="","",IFERROR(IF(P222<='Input & Settings'!$B$14,100,MAX(0,100-(P222-'Input & Settings'!$B$14)*20)),"")) | AA222: =IF(COUNTA(G222:P222)=0,"",ROUND(Q222*'Input & Settings'!$C$5+R222*'Input & Settings'!$C$6+S222*'Input & Settings'!$C$7+T222*'Input & Settings'!$C$8+U222*'Input & Settings'!$C$9+V222*'Input & Settings'!$C$10+W222*'Input & Settings'!$C$11+X222*'Input & Settings'!$C$12+Y222*'Input & Settings'!$C$13+Z222*'Input & Settings'!$C$14,1)) | AB222: =IF(OR(AA222="",E222=""),"",IFERROR(IF(AA222>=VLOOKUP(E222,'Input & Settings'!$F$5:$K$10,3,FALSE),"Outstanding",IF(AA222>=VLOOKUP(E222,'Input & Settings'!$F$5:$K$10,4,FALSE),"Exceeds Expectations",IF(AA222>=VLOOKUP(E222,'Input & Settings'!$F$5:$K$10,5,FALSE),"Meets Expectations",IF(AA222>=VLOOKUP(E222,'Input & Settings'!$F$5:$K$10,6,FALSE),"Needs Improvement","Performance Improvement Required")))),"")) | AC222: =IF(COUNTA(G222:P222)+COUNTA(AD222:AE222)>0,"Entered","") | AF222: =IF(AD222<>"",AD222,AA222) | AG222: =IF(AE222<>"",AE222,AB222) | AH222: =D222&"|"&B222 -> Alvaro Hernandez|June
A223: 2026 | B223: June | C223: Joshio Flores | D223: Sarah Clervil | F223: =IF(E223="","",IFERROR(VLOOKUP(E223,'Input & Settings'!$F$5:$G$10,2,FALSE),"")) | Q223: =IF(G223="","",IFERROR(MIN(100,G223/'Input & Settings'!$B$5*100),"")) | R223: =IF(H223="","",IFERROR(MIN(100,H223/'Input & Settings'!$B$6*100),"")) | S223: =IF(I223="","",IFERROR(MIN(100,I223/'Input & Settings'!$B$7*100),"")) | T223: =IF(J223="","",IFERROR(MIN(100,J223/'Input & Settings'!$B$8*100),"")) | U223: =IF(K223="","",IFERROR(MIN(100,K223/'Input & Settings'!$B$9*100),"")) | V223: =IF(L223="","",IFERROR(MIN(100,L223/'Input & Settings'!$B$10*100),"")) | W223: =IF(M223="","",IFERROR(IF(M223<='Input & Settings'!$B$11,100,MAX(0,100-(M223-'Input & Settings'!$B$11)*20)),"")) | X223: =IF(N223="","",IFERROR(MIN(100,N223/'Input & Settings'!$B$12*100),"")) | Y223: =IF(O223="","",IFERROR(MIN(100,O223/'Input & Settings'!$B$13*100),"")) | Z223: =IF(P223="","",IFERROR(IF(P223<='Input & Settings'!$B$14,100,MAX(0,100-(P223-'Input & Settings'!$B$14)*20)),"")) | AA223: =IF(COUNTA(G223:P223)=0,"",ROUND(Q223*'Input & Settings'!$C$5+R223*'Input & Settings'!$C$6+S223*'Input & Settings'!$C$7+T223*'Input & Settings'!$C$8+U223*'Input & Settings'!$C$9+V223*'Input & Settings'!$C$10+W223*'Input & Settings'!$C$11+X223*'Input & Settings'!$C$12+Y223*'Input & Settings'!$C$13+Z223*'Input & Settings'!$C$14,1)) | AB223: =IF(OR(AA223="",E223=""),"",IFERROR(IF(AA223>=VLOOKUP(E223,'Input & Settings'!$F$5:$K$10,3,FALSE),"Outstanding",IF(AA223>=VLOOKUP(E223,'Input & Settings'!$F$5:$K$10,4,FALSE),"Exceeds Expectations",IF(AA223>=VLOOKUP(E223,'Input & Settings'!$F$5:$K$10,5,FALSE),"Meets Expectations",IF(AA223>=VLOOKUP(E223,'Input & Settings'!$F$5:$K$10,6,FALSE),"Needs Improvement","Performance Improvement Required")))),"")) | AC223: =IF(COUNTA(G223:P223)+COUNTA(AD223:AE223)>0,"Entered","") | AF223: =IF(AD223<>"",AD223,AA223) | AG223: =IF(AE223<>"",AE223,AB223) | AH223: =D223&"|"&B223 -> Sarah Clervil|June
A224: 2026 | B224: June | C224: Joshio Flores | D224: Christopher Ovid | F224: =IF(E224="","",IFERROR(VLOOKUP(E224,'Input & Settings'!$F$5:$G$10,2,FALSE),"")) | Q224: =IF(G224="","",IFERROR(MIN(100,G224/'Input & Settings'!$B$5*100),"")) | R224: =IF(H224="","",IFERROR(MIN(100,H224/'Input & Settings'!$B$6*100),"")) | S224: =IF(I224="","",IFERROR(MIN(100,I224/'Input & Settings'!$B$7*100),"")) | T224: =IF(J224="","",IFERROR(MIN(100,J224/'Input & Settings'!$B$8*100),"")) | U224: =IF(K224="","",IFERROR(MIN(100,K224/'Input & Settings'!$B$9*100),"")) | V224: =IF(L224="","",IFERROR(MIN(100,L224/'Input & Settings'!$B$10*100),"")) | W224: =IF(M224="","",IFERROR(IF(M224<='Input & Settings'!$B$11,100,MAX(0,100-(M224-'Input & Settings'!$B$11)*20)),"")) | X224: =IF(N224="","",IFERROR(MIN(100,N224/'Input & Settings'!$B$12*100),"")) | Y224: =IF(O224="","",IFERROR(MIN(100,O224/'Input & Settings'!$B$13*100),"")) | Z224: =IF(P224="","",IFERROR(IF(P224<='Input & Settings'!$B$14,100,MAX(0,100-(P224-'Input & Settings'!$B$14)*20)),"")) | AA224: =IF(COUNTA(G224:P224)=0,"",ROUND(Q224*'Input & Settings'!$C$5+R224*'Input & Settings'!$C$6+S224*'Input & Settings'!$C$7+T224*'Input & Settings'!$C$8+U224*'Input & Settings'!$C$9+V224*'Input & Settings'!$C$10+W224*'Input & Settings'!$C$11+X224*'Input & Settings'!$C$12+Y224*'Input & Settings'!$C$13+Z224*'Input & Settings'!$C$14,1)) | AB224: =IF(OR(AA224="",E224=""),"",IFERROR(IF(AA224>=VLOOKUP(E224,'Input & Settings'!$F$5:$K$10,3,FALSE),"Outstanding",IF(AA224>=VLOOKUP(E224,'Input & Settings'!$F$5:$K$10,4,FALSE),"Exceeds Expectations",IF(AA224>=VLOOKUP(E224,'Input & Settings'!$F$5:$K$10,5,FALSE),"Meets Expectations",IF(AA224>=VLOOKUP(E224,'Input & Settings'!$F$5:$K$10,6,FALSE),"Needs Improvement","Performance Improvement Required")))),"")) | AC224: =IF(COUNTA(G224:P224)+COUNTA(AD224:AE224)>0,"Entered","") | AF224: =IF(AD224<>"",AD224,AA224) | AG224: =IF(AE224<>"",AE224,AB224) | AH224: =D224&"|"&B224 -> Christopher Ovid|June
A225: 2026 | B225: June | C225: Joshio Flores | D225: Rafael Godinez | E225: 1st Shift | F225: =IF(E225="","",IFERROR(VLOOKUP(E225,'Input & Settings'!$F$5:$G$10,2,FALSE),"")) -> High | Q225: =IF(G225="","",IFERROR(MIN(100,G225/'Input & Settings'!$B$5*100),"")) | R225: =IF(H225="","",IFERROR(MIN(100,H225/'Input & Settings'!$B$6*100),"")) | S225: =IF(I225="","",IFERROR(MIN(100,I225/'Input & Settings'!$B$7*100),"")) | T225: =IF(J225="","",IFERROR(MIN(100,J225/'Input & Settings'!$B$8*100),"")) | U225: =IF(K225="","",IFERROR(MIN(100,K225/'Input & Settings'!$B$9*100),"")) | V225: =IF(L225="","",IFERROR(MIN(100,L225/'Input & Settings'!$B$10*100),"")) | W225: =IF(M225="","",IFERROR(IF(M225<='Input & Settings'!$B$11,100,MAX(0,100-(M225-'Input & Settings'!$B$11)*20)),"")) | X225: =IF(N225="","",IFERROR(MIN(100,N225/'Input & Settings'!$B$12*100),"")) | Y225: =IF(O225="","",IFERROR(MIN(100,O225/'Input & Settings'!$B$13*100),"")) | Z225: =IF(P225="","",IFERROR(IF(P225<='Input & Settings'!$B$14,100,MAX(0,100-(P225-'Input & Settings'!$B$14)*20)),"")) | AA225: =IF(COUNTA(G225:P225)=0,"",ROUND(Q225*'Input & Settings'!$C$5+R225*'Input & Settings'!$C$6+S225*'Input & Settings'!$C$7+T225*'Input & Settings'!$C$8+U225*'Input & Settings'!$C$9+V225*'Input & Settings'!$C$10+W225*'Input & Settings'!$C$11+X225*'Input & Settings'!$C$12+Y225*'Input & Settings'!$C$13+Z225*'Input & Settings'!$C$14,1)) | AB225: =IF(OR(AA225="",E225=""),"",IFERROR(IF(AA225>=VLOOKUP(E225,'Input & Settings'!$F$5:$K$10,3,FALSE),"Outstanding",IF(AA225>=VLOOKUP(E225,'Input & Settings'!$F$5:$K$10,4,FALSE),"Exceeds Expectations",IF(AA225>=VLOOKUP(E225,'Input & Settings'!$F$5:$K$10,5,FALSE),"Meets Expectations",IF(AA225>=VLOOKUP(E225,'Input & Settings'!$F$5:$K$10,6,FALSE),"Needs Improvement","Performance Improvement Required")))),"")) | AC225: =IF(COUNTA(G225:P225)+COUNTA(AD225:AE225)>0,"Entered","") | AF225: =IF(AD225<>"",AD225,AA225) | AG225: =IF(AE225<>"",AE225,AB225) | AH225: =D225&"|"&B225 -> Rafael Godinez|June
A226: 2026 | B226: June | C226: Joshio Flores | D226: Dennis Mayorga | E226: 1st Shift Weekend | F226: =IF(E226="","",IFERROR(VLOOKUP(E226,'Input & Settings'!$F$5:$G$10,2,FALSE),"")) -> Normal | Q226: =IF(G226="","",IFERROR(MIN(100,G226/'Input & Settings'!$B$5*100),"")) | R226: =IF(H226="","",IFERROR(MIN(100,H226/'Input & Settings'!$B$6*100),"")) | S226: =IF(I226="","",IFERROR(MIN(100,I226/'Input & Settings'!$B$7*100),"")) | T226: =IF(J226="","",IFERROR(MIN(100,J226/'Input & Settings'!$B$8*100),"")) | U226: =IF(K226="","",IFERROR(MIN(100,K226/'Input & Settings'!$B$9*100),"")) | V226: =IF(L226="","",IFERROR(MIN(100,L226/'Input & Settings'!$B$10*100),"")) | W226: =IF(M226="","",IFERROR(IF(M226<='Input & Settings'!$B$11,100,MAX(0,100-(M226-'Input & Settings'!$B$11)*20)),"")) | X226: =IF(N226="","",IFERROR(MIN(100,N226/'Input & Settings'!$B$12*100),"")) | Y226: =IF(O226="","",IFERROR(MIN(100,O226/'Input & Settings'!$B$13*100),"")) | Z226: =IF(P226="","",IFERROR(IF(P226<='Input & Settings'!$B$14,100,MAX(0,100-(P226-'Input & Settings'!$B$14)*20)),"")) | AA226: =IF(COUNTA(G226:P226)=0,"",ROUND(Q226*'Input & Settings'!$C$5+R226*'Input & Settings'!$C$6+S226*'Input & Settings'!$C$7+T226*'Input & Settings'!$C$8+U226*'Input & Settings'!$C$9+V226*'Input & Settings'!$C$10+W226*'Input & Settings'!$C$11+X226*'Input & Settings'!$C$12+Y226*'Input & Settings'!$C$13+Z226*'Input & Settings'!$C$14,1)) | AB226: =IF(OR(AA226="",E226=""),"",IFERROR(IF(AA226>=VLOOKUP(E226,'Input & Settings'!$F$5:$K$10,3,FALSE),"Outstanding",IF(AA226>=VLOOKUP(E226,'Input & Settings'!$F$5:$K$10,4,FALSE),"Exceeds Expectations",IF(AA226>=VLOOKUP(E226,'Input & Settings'!$F$5:$K$10,5,FALSE),"Meets Expectations",IF(AA226>=VLOOKUP(E226,'Input & Settings'!$F$5:$K$10,6,FALSE),"Needs Improvement","Performance Improvement Required")))),"")) | AC226: =IF(COUNTA(G226:P226)+COUNTA(AD226:AE226)>0,"Entered","") | AF226: =IF(AD226<>"",AD226,AA226) | AG226: =IF(AE226<>"",AE226,AB226) | AH226: =D226&"|"&B226 -> Dennis Mayorga|June
A227: 2026 | B227: June | C227: Joshio Flores | D227: Jose Reyes-Navolskyi (Ivan) | E227: 2nd Shift | F227: =IF(E227="","",IFERROR(VLOOKUP(E227,'Input & Settings'!$F$5:$G$10,2,FALSE),"")) -> Normal | Q227: =IF(G227="","",IFERROR(MIN(100,G227/'Input & Settings'!$B$5*100),"")) | R227: =IF(H227="","",IFERROR(MIN(100,H227/'Input & Settings'!$B$6*100),"")) | S227: =IF(I227="","",IFERROR(MIN(100,I227/'Input & Settings'!$B$7*100),"")) | T227: =IF(J227="","",IFERROR(MIN(100,J227/'Input & Settings'!$B$8*100),"")) | U227: =IF(K227="","",IFERROR(MIN(100,K227/'Input & Settings'!$B$9*100),"")) | V227: =IF(L227="","",IFERROR(MIN(100,L227/'Input & Settings'!$B$10*100),"")) | W227: =IF(M227="","",IFERROR(IF(M227<='Input & Settings'!$B$11,100,MAX(0,100-(M227-'Input & Settings'!$B$11)*20)),"")) | X227: =IF(N227="","",IFERROR(MIN(100,N227/'Input & Settings'!$B$12*100),"")) | Y227: =IF(O227="","",IFERROR(MIN(100,O227/'Input & Settings'!$B$13*100),"")) | Z227: =IF(P227="","",IFERROR(IF(P227<='Input & Settings'!$B$14,100,MAX(0,100-(P227-'Input & Settings'!$B$14)*20)),"")) | AA227: =IF(COUNTA(G227:P227)=0,"",ROUND(Q227*'Input & Settings'!$C$5+R227*'Input & Settings'!$C$6+S227*'Input & Settings'!$C$7+T227*'Input & Settings'!$C$8+U227*'Input & Settings'!$C$9+V227*'Input & Settings'!$C$10+W227*'Input & Settings'!$C$11+X227*'Input & Settings'!$C$12+Y227*'Input & Settings'!$C$13+Z227*'Input & Settings'!$C$14,1)) | AB227: =IF(OR(AA227="",E227=""),"",IFERROR(IF(AA227>=VLOOKUP(E227,'Input & Settings'!$F$5:$K$10,3,FALSE),"Outstanding",IF(AA227>=VLOOKUP(E227,'Input & Settings'!$F$5:$K$10,4,FALSE),"Exceeds Expectations",IF(AA227>=VLOOKUP(E227,'Input & Settings'!$F$5:$K$10,5,FALSE),"Meets Expectations",IF(AA227>=VLOOKUP(E227,'Input & Settings'!$F$5:$K$10,6,FALSE),"Needs Improvement","Performance Improvement Required")))),"")) | AC227: =IF(COUNTA(G227:P227)+COUNTA(AD227:AE227)>0,"Entered","") | AF227: =IF(AD227<>"",AD227,AA227) | AG227: =IF(AE227<>"",AE227,AB227) | AH227: =D227&"|"&B227 -> Jose Reyes-Navolskyi (Ivan)|June
A228: 2026 | B228: June | C228: Joshio Flores | D228: Jonathan Davila | F228: =IF(E228="","",IFERROR(VLOOKUP(E228,'Input & Settings'!$F$5:$G$10,2,FALSE),"")) | Q228: =IF(G228="","",IFERROR(MIN(100,G228/'Input & Settings'!$B$5*100),"")) | R228: =IF(H228="","",IFERROR(MIN(100,H228/'Input & Settings'!$B$6*100),"")) | S228: =IF(I228="","",IFERROR(MIN(100,I228/'Input & Settings'!$B$7*100),"")) | T228: =IF(J228="","",IFERROR(MIN(100,J228/'Input & Settings'!$B$8*100),"")) | U228: =IF(K228="","",IFERROR(MIN(100,K228/'Input & Settings'!$B$9*100),"")) | V228: =IF(L228="","",IFERROR(MIN(100,L228/'Input & Settings'!$B$10*100),"")) | W228: =IF(M228="","",IFERROR(IF(M228<='Input & Settings'!$B$11,100,MAX(0,100-(M228-'Input & Settings'!$B$11)*20)),"")) | X228: =IF(N228="","",IFERROR(MIN(100,N228/'Input & Settings'!$B$12*100),"")) | Y228: =IF(O228="","",IFERROR(MIN(100,O228/'Input & Settings'!$B$13*100),"")) | Z228: =IF(P228="","",IFERROR(IF(P228<='Input & Settings'!$B$14,100,MAX(0,100-(P228-'Input & Settings'!$B$14)*20)),"")) | AA228: =IF(COUNTA(G228:P228)=0,"",ROUND(Q228*'Input & Settings'!$C$5+R228*'Input & Settings'!$C$6+S228*'Input & Settings'!$C$7+T228*'Input & Settings'!$C$8+U228*'Input & Settings'!$C$9+V228*'Input & Settings'!$C$10+W228*'Input & Settings'!$C$11+X228*'Input & Settings'!$C$12+Y228*'Input & Settings'!$C$13+Z228*'Input & Settings'!$C$14,1)) | AB228: =IF(OR(AA228="",E228=""),"",IFERROR(IF(AA228>=VLOOKUP(E228,'Input & Settings'!$F$5:$K$10,3,FALSE),"Outstanding",IF(AA228>=VLOOKUP(E228,'Input & Settings'!$F$5:$K$10,4,FALSE),"Exceeds Expectations",IF(AA228>=VLOOKUP(E228,'Input & Settings'!$F$5:$K$10,5,FALSE),"Meets Expectations",IF(AA228>=VLOOKUP(E228,'Input & Settings'!$F$5:$K$10,6,FALSE),"Needs Improvement","Performance Improvement Required")))),"")) | AC228: =IF(COUNTA(G228:P228)+COUNTA(AD228:AE228)>0,"Entered","") | AF228: =IF(AD228<>"",AD228,AA228) | AG228: =IF(AE228<>"",AE228,AB228) | AH228: =D228&"|"&B228 -> Jonathan Davila|June
A229: 2026 | B229: June | C229: Rafael Amaro | D229: Kevin Luburd | E229: 2nd Shift Weekend | F229: =IF(E229="","",IFERROR(VLOOKUP(E229,'Input & Settings'!$F$5:$G$10,2,FALSE),"")) -> Low | Q229: =IF(G229="","",IFERROR(MIN(100,G229/'Input & Settings'!$B$5*100),"")) | R229: =IF(H229="","",IFERROR(MIN(100,H229/'Input & Settings'!$B$6*100),"")) | S229: =IF(I229="","",IFERROR(MIN(100,I229/'Input & Settings'!$B$7*100),"")) | T229: =IF(J229="","",IFERROR(MIN(100,J229/'Input & Settings'!$B$8*100),"")) | U229: =IF(K229="","",IFERROR(MIN(100,K229/'Input & Settings'!$B$9*100),"")) | V229: =IF(L229="","",IFERROR(MIN(100,L229/'Input & Settings'!$B$10*100),"")) | W229: =IF(M229="","",IFERROR(IF(M229<='Input & Settings'!$B$11,100,MAX(0,100-(M229-'Input & Settings'!$B$11)*20)),"")) | X229: =IF(N229="","",IFERROR(MIN(100,N229/'Input & Settings'!$B$12*100),"")) | Y229: =IF(O229="","",IFERROR(MIN(100,O229/'Input & Settings'!$B$13*100),"")) | Z229: =IF(P229="","",IFERROR(IF(P229<='Input & Settings'!$B$14,100,MAX(0,100-(P229-'Input & Settings'!$B$14)*20)),"")) | AA229: =IF(COUNTA(G229:P229)=0,"",ROUND(Q229*'Input & Settings'!$C$5+R229*'Input & Settings'!$C$6+S229*'Input & Settings'!$C$7+T229*'Input & Settings'!$C$8+U229*'Input & Settings'!$C$9+V229*'Input & Settings'!$C$10+W229*'Input & Settings'!$C$11+X229*'Input & Settings'!$C$12+Y229*'Input & Settings'!$C$13+Z229*'Input & Settings'!$C$14,1)) | AB229: =IF(OR(AA229="",E229=""),"",IFERROR(IF(AA229>=VLOOKUP(E229,'Input & Settings'!$F$5:$K$10,3,FALSE),"Outstanding",IF(AA229>=VLOOKUP(E229,'Input & Settings'!$F$5:$K$10,4,FALSE),"Exceeds Expectations",IF(AA229>=VLOOKUP(E229,'Input & Settings'!$F$5:$K$10,5,FALSE),"Meets Expectations",IF(AA229>=VLOOKUP(E229,'Input & Settings'!$F$5:$K$10,6,FALSE),"Needs Improvement","Performance Improvement Required")))),"")) | AC229: =IF(COUNTA(G229:P229)+COUNTA(AD229:AE229)>0,"Entered","") | AF229: =IF(AD229<>"",AD229,AA229) | AG229: =IF(AE229<>"",AE229,AB229) | AH229: =D229&"|"&B229 -> Kevin Luburd|June
